Workbook

Sheet June
A1: Date | B1: Milking | C1: Shobha | D1: Devaki | E1: Sita | F1: Lakshmi | H1: Total (Litres) | I1: Daily Milk collection
A2: 45809 | B2: Morning | C2: 3 | H2: =SUM(C2:F2) -> 3 | I2: =H2+I4 -> 6.5
B3: Evening | C3: 2 | H3: =SUM(C3:F3) -> 2
A4: 45810 | B4: Morning | C4: 2 | H4: =SUM(C4:F4) -> 2 | I4: =H4+H5 -> 3.5
B5: Evening | C5: 1.5 | H5: =SUM(C5:F5) -> 1.5
A6: 45811 | B6: Morning | C6: 2 | H6: =SUM(C6:F6) -> 2 | I6: =H6+H7 -> 3.5
B7: Evening | C7: 1.5 | H7: =SUM(C7:F7) -> 1.5
A8: 45812 | B8: Morning | C8: 2.8 | H8: =SUM(C8:F8) -> 2.8 | I8: =H8+H9 -> 4.1
B9: Evening | C9: 1.3 | H9: =SUM(C9:F9) -> 1.3
A10: 45813 | B10: Morning | C10: 2.8 | H10: =SUM(C10:F10) -> 2.8 | I10: =H10+H11 -> 4.4
B11: Evening | C11: 1.6 | H11: =SUM(C11:F11) -> 1.6
A12: 45814 | B12: Morning | C12: 2.5 | H12: =SUM(C12:F12) -> 2.5 | I12: =H12+H13 -> 4
B13: Evening | C13: 1.5 | H13: =SUM(C13:F13) -> 1.5
A14: 45815 | B14: Morning | C14: 3 | H14: =SUM(C14:F14) -> 3 | I14: =H14+H15 -> 4.5
B15: Evening | C15: 1.5 | H15: =SUM(C15:F15) -> 1.5
A16: 45816 | B16: Morning | C16: 3.5 | H16: =SUM(C16:F16) -> 3.5 | I16: =H16+H17 -> 4.9
B17: Evening | C17: 1.4 | H17: =SUM(C17:F17) -> 1.4
A18: 45817 | B18: Morning | C18: 3.5 | H18: =SUM(C18:F18) -> 3.5 | I18: =H18+H19 -> 5
B19: Evening | C19: 1.5 | H19: =SUM(C19:F19) -> 1.5
A20: 45818 | B20: Morning | C20: 3 | H20: =SUM(C20:F20) -> 3 | I20: =H20+H21 -> 4.5
B21: Evening | C21: 1.5 | H21: =SUM(C21:F21) -> 1.5
A22: 45819 | B22: Morning | C22: 2.5 | D22: 4.5 | E22: 4 | H22: =SUM(C22:F22) -> 11 | I22: =H22+H23 -> 20.8
B23: Evening | C23: 1.3 | D23: 4.5 | E23: 4 | H23: =SUM(C23:F23) -> 9.8
A24: 45820 | B24: Morning | C24: 2.5 | D24: 4.5 | E24: 4 | H24: =SUM(C24:F24) -> 11 | I24: =H24+H25 -> 21
B25: Evening | C25: 1.5 | D25: 4.5 | E25: 4 | H25: =SUM(C25:F25) -> 10
A26: 45821 | B26: Morning | C26: 2.5 | D26: 4.5 | E26: 4 | H26: =SUM(C26:F26) -> 11 | I26: =H26+H27 -> 21
B27: Evening | C27: 1.5 | D27: 4.5 | E27: 4 | H27: =SUM(C27:F27) -> 10
A28: 45822 | B28: Morning | C28: 3 | D28: 4.5 | E28: 3 | H28: =SUM(C28:F28) -> 10.5 | I28: =H28+H29 -> 19.5
B29: Evening | C29: 1.5 | D29: 4.5 | E29: 3 | H29: =SUM(C29:F29) -> 9
A30: 45823 | B30: Morning | C30: 2.5 | D30: 4.5 | E30: 3 | H30: =SUM(C30:F30) -> 10 | I30: =H30+H31 -> 19
B31: Evening | C31: 1.5 | D31: 4.5 | E31: 3 | H31: =SUM(C31:F31) -> 9
A32: 45824 | B32: Morning | C32: 3 | D32: 4.5 | E32: 3 | H32: =SUM(C32:F32) -> 10.5 | I32: =H32+H33 -> 19.3
B33: Evening | C33: 2 | D33: 4.4 | E33: 2.4 | H33: =SUM(C33:F33) -> 8.8
A34: 45825 | B34: Morning | C34: 3.3 | D34: 4.5 | E34: 3.1 | H34: =SUM(C34:F34) -> 10.9 | I34: =H34+H35 -> 19.7
B35: Evening | C35: 2.7 | D35: 4.5 | E35: 1.6 | H35: =SUM(C35:F35) -> 8.8
A36: 45826 | B36: Morning | C36: 3.5 | D36: 5.2 | E36: 2.5 | H36: =SUM(C36:F36) -> 11.2 | I36: =H36+H37 -> 19.7
B37: Evening | C37: 2 | D37: 4.5 | E37: 2 | H37: =SUM(C37:F37) -> 8.5
A38: 45827 | B38: Morning | C38: 3.5 | D38: 4.4 | E38: 3 | H38: =SUM(C38:F38) -> 10.9 | I38: =H38+H39 -> 18.9
B39: Evening | C39: 2 | D39: 4 | E39: 2 | H39: =SUM(C39:F39) -> 8
A40: 45828 | B40: Morning | C40: 3 | D40: 4.5 | E40: 1.9 | H40: =SUM(C40:F40) -> 9.4 | I40: =H40+H41 -> 16.9
...

Sheet June 2026
A1: Datemm- | B1: Milking | C1: Shobha | D1: Devaki | E1: Sita | F1: Lakshmi | G1: Mruga | H1: Radha | I1: Shravani | J1: Uma | K1: Parvati | L1: Durga | M1: Ganga | N1: Yamuna | O1: Kapila | P1: Sindhu | Q1: Total (Litres) | R1: Daily total (Litres) | T1: Transfer to milk sale | U1: Transfer to ghee | V1: Balance milk | W1: stored milk | X1: satyajits home | Y1: Amit bhave | Z1: bal | AA1: actual sale | AB1: return from sale | AC1: diff | AD1: bal
A2: 46174 | B2: Morning | F2: 2.64 | G2: 3.26 | H2: 0 | I2: 1.18 | J2: 2.64 | K2: 2.72 | L2: 4.16 | M2: 2.8 | N2: 3.8 | Q2: =sum(C2:P2) -> 23.2 | R2: =Q2+Q3 -> 45.76
B3: Evening | F3: 2.75 | G3: 2.81 | H3: 0 | I3: 1.27 | J3: 2.74 | K3: 2.99 | L3: 4 | M3: 2.6 | N3: 3.4 | Q3: =SUM(C3:N3) -> 22.56
A4: 46175 | B4: Morning | F4: 2.61 | G4: 2.47 | H4: 0 | I4: 0.94 | J4: 2.3 | K4: 2.86 | L4: 3.1 | M4: 2.61 | N4: 3.52 | Q4: =sum(C4:P4) -> 20.41 | R4: =Q4+Q5 -> 45.19
B5: Evening | F5: 2.43 | G5: 2.45 | H5: 0 | I5: 1 | J5: 3.03 | K5: 2.91 | L5: 4.94 | M5: 3.85 | N5: 4.17 | Q5: =sum(C5:P5) -> 24.78
A6: 46176 | B6: Morning | F6: 2.64 | G6: 3 | H6: 0 | I6: 1.3 | J6: 3.04 | K6: 3.51 | L6: 3.95 | M6: 2.37 | N6: 4.02 | Q6: =sum(C6:P6) -> 23.83 | R6: =Q6+Q7 -> 50.34
B7: Evening | F7: 2.88 | G7: 3.92 | H7: 0 | I7: 1.4 | J7: 2.59 | K7: 3.58 | L7: 4.37 | M7: 3.21 | N7: 4.56 | Q7: =sum(C7:P7) -> 26.51
A8: 46177 | B8: Morning | F8: 3.31 | G8: 3.62 | H8: 0 | I8: 0.93 | J8: 3.98 | K8: 2.7 | L8: 2.65 | M8: 3.63 | N8: 3.01 | Q8: =sum(C8:P8) -> 23.83 | R8: =Q8+Q9 -> 47.77
B9: Evening | F9: 3.02 | G9: 3.69 | H9: 0 | I9: 0.5 | J9: 2.74 | K9: 2.92 | L9: 4.01 | M9: 3.03 | N9: 4.03 | Q9: =sum(C9:P9) -> 23.94
A10: 46178 | B10: Morning | F10: 2.93 | G10: 3.95 | H10: 0 | I10: 0.5 | J10: 2.76 | K10: 3.4 | L10: 4.32 | M10: 2.71 | N10: 3.9 | Q10: =sum(C10:P10) -> 24.47 | R10: =Q10+Q11 -> 52.47
B11: Evening | F11: 2.89 | G11: 3.33 | H11: 0 | I11: 0.5 | J11: 2.19 | K11: 3.24 | L11: 6.35 | M11: 2.56 | N11: 4.54 | P11: 2.4 | Q11: =sum(C11:P11) -> 28
A12: 46179 | B12: Morning | F12: 3.15 | G12: 3.81 | H12: 0 | I12: 0 | J12: 2.72 | K12: 2.83 | L12: 4.17 | M12: 3 | N12: 4.29 | O12: 0 | P12: 0 | Q12: =sum(C12:P12) -> 23.97 | R12: =Q12+Q13 -> 47.83
B13: Evening | F13: 2.79 | G13: 2.94 | H13: 0 | I13: 0.5 | J13: 2.4 | K13: 2.89 | L13: 3.87 | M13: 3.21 | N13: 2.3 | O13: 1.4 | P13: 1.56 | Q13: =sum(C13:P13) -> 23.86
A14: 46180 | B14: Morning | F14: 2.58 | G14: 3.27 | H14: 0 | I14: 0.5 | J14: 2.32 | K14: 2.74 | L14: 3.4 | M14: 3.32 | N14: 4.35 | O14: 1 | P14: 4.5 | Q14: =sum(C14:P14) -> 27.98 | R14: =Q14+Q15 -> 53.14
B15: Evening | F15: 2.35 | G15: 3.18 | H15: 0 | I15: 1.36 | J15: 2.57 | K15: 2.39 | L15: 3.07 | M15: 2.73 | N15: 4.17 | O15: 0.5 | P15: 2.84 | Q15: =sum(C15:P15) -> 25.16
A16: 46181 | B16: Morning | F16: 3.43 | G16: 4.17 | H16: 0 | I16: 0.5 | J16: 3.277 | K16: 2.41 | L16: 4.05 | M16: 3 | N16: 4.37 | O16: 1 | P16: 4.39 | Q16: =sum(C16:P16) -> 30.597 | R16: =Q16+Q17 -> 54.647
B17: Evening | F17: 1.79 | G17: 2.92 | H17: 0 | I17: 0 | J17: 2.31 | K17: 3.05 | L17: 3.76 | M17: 2.79 | N17: 3.72 | O17: 0.5 | P17: 3.21 | Q17: =sum(C17:P17) -> 24.05
A18: 46182 | B18: Morning | F18: 3.4 | G18: 3.71 | H18: 0 | I18: 0 | J18: 2.38 | K18: 4 | L18: 4.23 | M18: 2.3 | N18: 4.81 | O18: 0 | P18: 4 | Q18: =sum(C18:P18) -> 28.83 | R18: =Q18+Q19 -> 57.4
B19: Evening | F19: 2.4 | G19: 3.74 | H19: 0 | I19: 1.5 | J19: 2.3 | K19: 2.14 | L19: 4.2 | M19: 3 | N19: 4.45 | O19: 1.14 | P19: 3.7 | Q19: =sum(C19:P19) -> 28.57
A20: 46183 | B20: Morning | F20: 2.7 | G20: 3.65 | H20: 0 | I20: 0 | J20: 2.73 | K20: 2.28 | L20: 4.11 | M20: 2.96 | N20: 4.3 | O20: 0 | P20: 3.6 | Q20: =sum(C20:P20) -> 26.33 | R20: =Q20+Q21 -> 48.44
B21: Evening | F21: 2.12 | G21: 3.04 | H21: 0 | I21: 0 | J21: 2.21 | K21: 2.3 | L21: 3.62 | M21: 2.34 | N21: 3.22 | O21: 0 | P21: 3.26 | Q21: =sum(C21:P21) -> 22.11
A22: 46184 | B22: Morning | F22: 2.71 | G22: 4.11 | H22: 0 | I22: 0 | J22: 2.1 | K22: 2.29 | L22: 4.48 | M22: 2.85 | N22: 3.65 | O22: 0 | P22: 0 | Q22: =sum(C22:P22) -> 22.19 | R22: =Q22+Q23 -> 43.57
B23: Evening | F23: 2.4 | G23: 3.26 | H23: 0 | I23: 0 | J23: 1.92 | K23: 2.4 | L23: 3.4 | M23: 2.54 | N23: 3.31 | O23: 0 | P23: 2.15 | Q23: =sum(C23:P23) -> 21.38
A24: 46185 | B24: Morning | F24: 2.82 | G24: 3.6 | H24: 0 | I24: 0.98 | J24: 2.45 | K24: 2.75 | L24: 4.07 | M24: 2.95 | N24: 3.76 | O24: 1.2 | P24: 3.84 | Q24: =sum(C24:P24) -> 28.42 | R24: =Q24+Q25 -> 51.51
B25: Evening | F25: 2.36 | G25: 2.96 | H25: 0 | I25: 0.9 | J25: 2.09 | K25: 1.63 | L25: 3.4 | M25: 2.5 | N25: 3.16 | O25: 1.1 | P25: 2.99 | Q25: =sum(C25:P25) -> 23.09
A26: 46186 | B26: Morning | F26: 3.4 | G26: 3.75 | H26: 0 | I26: 0 | J26: 2.61 | K26: 2.84 | L26: 3.71 | M26: 3.2 | N26: 4.59 | O26: 2.1 | P26: 3.95 | Q26: =sum(C26:P26) -> 30.15 | R26: =Q26+Q27 -> 57.98
B27: Evening | F27: 3.56 | G27: 3.32 | H27: 0 | I27: 0.94 | J27: 2.61 | K27: 2.56 | L27: 3.9 | M27: 2.6 | N27: 3.76 | O27: 1.79 | P27: 2.79 | Q27: =sum(C27:P27) -> 27.83
A28: 46187 | B28: Morning | F28: 3.59 | G28: 3.93 | H28: 0 | I28: 0.8 | J28: 2.76 | K28: 2.67 | L28: 4.27 | M28: 3.29 | N28: 4.6 | O28: 1.84 | P28: 4.2 | Q28: =sum(C28:P28) -> 31.95 | R28: =Q28+Q29 -> 54.94
B29: Evening | F29: 2.56 | G29: 2.7 | H29: 0 | I29: 0.83 | J29: 2.03 | K29: 2.76 | L29: 3.2 | M29: 2.21 | N29: 3.53 | O29: 0 | P29: 3.17 | Q29: =sum(C29:P29) -> 22.99
A30: 46188 | B30: Morning | F30: 3.55 | G30: 3.33 | H30: 0 | I30: 1.7 | J30: 2.58 | K30: 2.9 | L30: 4.16 | M30: 3 | N30: 4 | O30: 1 | P30: 3.95 | Q30: =sum(C30:P30) -> 30.17 | R30: =Q30+Q31 -> 52.08
B31: Evening | F31: 2.88 | G31: 2.93 | H31: 0 | I31: 0 | J31: 1.99 | K31: 2.19 | L31: 3.28 | M31: 2.35 | N31: 2.59 | O31: 0.5 | P31: 3.2 | Q31: =sum(C31:P31) -> 21.91
A32: 46189 | B32: Morning | Q32: =sum(C32:P32) -> 0 | R32: =Q32+Q33 -> 0
B33: Evening | Q33: =sum(C33:P33) -> 0
A34: 46190 | B34: Morning | Q34: =sum(C34:P34) -> 0 | R34: =Q34+Q35 -> 0
B35: Evening | Q35: =sum(C35:P35) -> 0
A36: 46191 | B36: Morning | Q36: =sum(C36:P36) -> 0 | R36: =Q36+Q37 -> 0
B37: Evening | Q37: =sum(C37:P37) -> 0
A38: 46192 | B38: Morning | Q38: =sum(C38:P38) -> 0 | R38: =Q38+Q39 -> 0
B39: Evening | Q39: =sum(C39:P39) -> 0
A40: 46193 | B40: Morning | Q40: =sum(C40:P40) -> 0 | R40: =Q40+Q41 -> 0
...

Sheet June Summary
A1: Cow Name | B1: Total Milk (Litres)
A2: Total | B2: =Sum(B3:B12) -> 336.7
A4: Shobha | B4: =SUM(June!C2:C61) -> 141.7
A5: Devaki | B5: =SUM(June!D2:D61) -> 116.3
A6: Sita | B6: =SUM(June!E2:E61) -> 78.7
A7: Lakshmi | B7: =sum(June!F2:F61) -> 0
A8: Mruga

Sheet July
A1: Date | B1: Milking | C1: Shobha | D1: Devaki | E1: Sita | F1: Lakshmi | H1: Total (Litres) | I1: Daily total (Litres)
A2: 45839 | B2: Morning | C2: 4 | D2: 0 | E2: 0.5 | H2: =SUM(C2:F2) -> 4.5 | I2: =H2+H3 -> 7.7
B3: Evening | C3: 2.5 | E3: 0.7 | H3: =SUM(C3:F3) -> 3.2
A4: 45840 | B4: Morning | C4: 3.5 | D4: 0 | E4: 0.5 | H4: =SUM(C4:F4) -> 4 | I4: =H4+H5 -> 6.5
B5: Evening | C5: 2.5 | D5: 0 | E5: 0 | H5: =SUM(C5:F5) -> 2.5
A6: 45841 | B6: Morning | C6: 3.5 | D6: 0 | E6: 0.5 | H6: =SUM(C6:F6) -> 4 | I6: =H6+H7 -> 6.5
B7: Evening | C7: 2.5 | D7: 0 | E7: 0 | H7: =SUM(C7:F7) -> 2.5
A8: 45842 | B8: Morning | C8: 4.5 | D8: 0 | E8: 0 | H8: =SUM(C8:F8) -> 4.5 | I8: =H8+H9 -> 8
B9: Evening | C9: 3 | D9: 0 | E9: 0.5 | H9: =SUM(C9:F9) -> 3.5
A10: 45843 | B10: Morning | C10: 4 | D10: 0 | E10: 1 | H10: =SUM(C10:F10) -> 5 | I10: =H10+H11 -> 8.5
B11: Evening | C11: 2.5 | D11: 0 | E11: 1 | H11: =SUM(C11:F11) -> 3.5
A12: 45844 | B12: Morning | C12: 4 | D12: 0 | E12: 1 | H12: =SUM(C12:F12) -> 5 | I12: =H12+H13 -> 9.3
B13: Evening | C13: 3.1 | D13: 0 | E13: 1.2 | H13: =SUM(C13:F13) -> 4.3
A14: 45845 | B14: Morning | C14: 4 | D14: 0.5 | E14: 0.5 | H14: =SUM(C14:F14) -> 5 | I14: =H14+H15 -> 9
B15: Evening | C15: 3 | D15: 0 | E15: 1 | H15: =SUM(C15:F15) -> 4
A16: 45846 | B16: Morning | C16: 4.5 | D16: 0.5 | E16: 0.5 | H16: =SUM(C16:F16) -> 5.5 | I16: =H16+H17 -> 9
B17: Evening | C17: 3 | D17: 0.5 | E17: 0 | H17: =SUM(C17:F17) -> 3.5
A18: 45847 | B18: Morning | C18: 5 | D18: 1.9 | E18: 1.5 | H18: =SUM(C18:F18) -> 8.4 | I18: =H18+H19 -> 13.4
B19: Evening | C19: 3 | D19: 1.5 | E19: 0.5 | H19: =SUM(C19:F19) -> 5
A20: 45848 | B20: Morning | C20: 4.7 | D20: 2 | E20: 1.5 | H20: =SUM(C20:F20) -> 8.2 | I20: =H20+H21 -> 15.1
B21: Evening | C21: 3.5 | D21: 1.4 | E21: 2 | H21: =SUM(C21:F21) -> 6.9
A22: 45849 | B22: Morning | C22: 5 | D22: 1.2 | E22: 2 | F22: 4 | H22: =SUM(C22:F22) -> 12.2 | I22: =H22+H23 -> 20.4
B23: Evening | C23: 2.2 | D23: 1.5 | E23: 1 | F23: 3.5 | H23: =SUM(C23:F23) -> 8.2
A24: 45850 | B24: Morning | C24: 5 | D24: 2 | E24: 2 | F24: 3.5 | H24: =SUM(C24:F24) -> 12.5 | I24: =H24+H25 -> 20.7
B25: Evening | C25: 3 | D25: 1.7 | F25: 3.5 | H25: =SUM(C25:F25) -> 8.2
A26: 45851 | B26: Morning | C26: 5.4 | D26: 2.8 | E26: 2 | F26: 3.8 | H26: =SUM(C26:F26) -> 14 | I26: =H26+H27 -> 23
B27: Evening | C27: 3 | D27: 1.5 | E27: 1 | F27: 3.5 | H27: =SUM(C27:F27) -> 9
A28: 45852 | B28: Morning | C28: 5 | D28: 1.8 | E28: 1.5 | F28: 3.5 | H28: =SUM(C28:F28) -> 11.8 | I28: =H28+H29 -> 21.3
B29: Evening | C29: 3.5 | D29: 2 | E29: 1 | F29: 3 | H29: =SUM(C29:F29) -> 9.5
A30: 45853 | B30: Morning | C30: 4 | D30: 2.5 | E30: 1.5 | F30: 3 | H30: =SUM(C30:F30) -> 11 | I30: =H30+H31 -> 21.3
B31: Evening | C31: 3.8 | D31: 2 | E31: 1.5 | F31: 3 | H31: =SUM(C31:F31) -> 10.3
A32: 45854 | B32: Morning | C32: 4.6 | D32: 2 | E32: 1.4 | F32: 3 | H32: =SUM(C32:F32) -> 11 | I32: =H32+H33 -> 22.2
B33: Evening | C33: 3.5 | D33: 2.5 | E33: 2.2 | F33: 3 | H33: =SUM(C33:F33) -> 11.2
A34: 45855 | B34: Morning | C34: 4.2 | D34: 2 | E34: 2 | F34: 3.5 | H34: =SUM(C34:F34) -> 11.7 | I34: =H34+H35 -> 20.3
B35: Evening | C35: 3.1 | D35: 1 | E35: 1.5 | F35: 3 | H35: =SUM(C35:F35) -> 8.6
A36: 45856 | B36: Morning | C36: 5 | D36: 2.5 | E36: 2 | F36: 3.5 | H36: =SUM(C36:F36) -> 13 | I36: =H36+H37 -> 22.5
B37: Evening | C37: 3 | D37: 2 | E37: 1.5 | F37: 3 | H37: =SUM(C37:F37) -> 9.5
A38: 45857 | B38: Morning | C38: 5.7 | D38: 2.5 | E38: 1.5 | F38: 3 | H38: =SUM(C38:F38) -> 12.7 | I38: =H38+H39 -> 23.2
B39: Evening | C39: 3 | D39: 2 | E39: 1.5 | F39: 4 | H39: =SUM(C39:F39) -> 10.5
A40: 45858 | B40: Morning | C40: 4.9 | D40: 2 | E40: 2 | F40: 4.5 | H40: =SUM(C40:F40) -> 13.4 | I40: =H40+H41 -> 23.8
...

Sheet July Summary
A1: Cow Name | B1: Total Milk (Litres)
A2: Total | B2: =Sum(B3:B12) -> 572.9
A4: Shobha | B4: =SUM(July!C2:C63) -> 238.1
A5: Devaki | B5: =SUM(July!D2:D63) -> 87
A6: Sita | B6: =SUM(July!E2:E63) -> 88.6
A7: Lakshmi | B7: =sum(July!F2:F63) -> 159.2
A8: Mruga

Sheet August
A1: Date | B1: Milking | C1: Shobha | D1: Devaki | E1: Sita | F1: Lakshmi | H1: Total (Litres) | I1: Daily total (Litres)
A2: 45870 | B2: Morning | C2: 4.7 | D2: 2 | E2: 2.4 | F2: 4.5 | H2: =SUM(C2:F2) -> 13.6 | I2: =H2+H3 -> 24.6
B3: Evening | C3: 3.5 | D3: 1.5 | E3: 1.5 | F3: 4.5 | H3: =SUM(C3:F3) -> 11
A4: 45871 | B4: Morning | C4: 4.9 | D4: 2 | E4: 2.4 | F4: 5 | H4: =SUM(C4:F4) -> 14.3 | I4: =H4+H5 -> 25.8
B5: Evening | C5: 4.6 | D5: 1.5 | E5: 1.7 | F5: 3.7 | H5: =SUM(C5:F5) -> 11.5
A6: 45872 | B6: Morning | C6: 4.5 | D6: 2 | E6: 2.5 | F6: 4.5 | H6: =SUM(C6:F6) -> 13.5 | I6: =H6+H7 -> 23.2
B7: Evening | C7: 1.5 | D7: 1.5 | E7: 2.5 | F7: 4.2 | H7: =SUM(C7:F7) -> 9.7
A8: 45873 | B8: Morning | C8: 4.9 | D8: 1.9 | E8: 2.5 | F8: 3.5 | H8: =SUM(C8:F8) -> 12.8 | I8: =H8+H9 -> 23.8
B9: Evening | C9: 3 | D9: 2 | E9: 2 | F9: 4 | H9: =SUM(C9:F9) -> 11
A10: 45874 | B10: Morning | C10: 4.4 | D10: 2 | E10: 2.5 | F10: 4.2 | H10: =SUM(C10:F10) -> 13.1 | I10: =H10+H11 -> 23.1
B11: Evening | C11: 2.5 | D11: 2 | E11: 2 | F11: 3.5 | H11: =SUM(C11:F11) -> 10
A12: 45875 | B12: Morning | C12: 4.5 | D12: 2 | E12: 2.5 | F12: 3.4 | H12: =SUM(C12:F12) -> 12.4 | I12: =H12+H13 -> 21.6
B13: Evening | C13: 2.7 | D13: 1.5 | E13: 1.5 | F13: 3.5 | H13: =SUM(C13:F13) -> 9.2
A14: 45876 | B14: Morning | C14: 5.5 | D14: 2 | E14: 2.5 | F14: 4.5 | H14: =SUM(C14:F14) -> 14.5 | I14: =H14+H15 -> 25.6
B15: Evening | C15: 3.4 | D15: 2 | E15: 2 | F15: 3.7 | H15: =SUM(C15:F15) -> 11.1
A16: 45877 | B16: Morning | C16: 5 | D16: 2.4 | E16: 2.5 | F16: 4.4 | H16: =SUM(C16:F16) -> 14.3 | I16: =H16+H17 -> 25.3
B17: Evening | C17: 3 | D17: 2 | E17: 2 | F17: 4 | H17: =SUM(C17:F17) -> 11
A18: 45878 | B18: Morning | C18: 5.4 | D18: 2 | E18: 2.5 | F18: 4.5 | H18: =SUM(C18:F18) -> 14.4 | I18: =H18+H19 -> 25.7
B19: Evening | C19: 3.5 | D19: 1.9 | E19: 2 | F19: 3.9 | H19: =SUM(C19:F19) -> 11.3
A20: 45879 | B20: Morning | C20: 4.5 | D20: 2 | E20: 2.5 | F20: 4 | H20: =SUM(C20:F20) -> 13 | I20: =H20+H21 -> 23.1
B21: Evening | C21: 3.4 | D21: 1.7 | E21: 2 | F21: 3 | H21: =SUM(C21:F21) -> 10.1
A22: 45880 | B22: Morning | C22: 5.5 | D22: 2 | E22: 2.3 | F22: 3.4 | H22: =SUM(C22:F22) -> 13.2 | I22: =H22+H23 -> 23.8
B23: Evening | C23: 3 | D23: 2 | E23: 2.1 | F23: 3.5 | H23: =SUM(C23:F23) -> 10.6
A24: 45881 | B24: Morning | C24: 4.7 | D24: 2.2 | E24: 2.5 | F24: 4 | H24: =SUM(C24:F24) -> 13.4 | I24: =H24+H25 -> 24.1
B25: Evening | C25: 2.5 | D25: 2 | E25: 2.2 | F25: 4 | H25: =SUM(C25:F25) -> 10.7
A26: 45882 | B26: Morning | C26: 5.4 | D26: 2.2 | E26: 2.5 | F26: 4.4 | H26: =SUM(C26:F26) -> 14.5 | I26: =H26+H27 -> 25.1
B27: Evening | C27: 2.9 | D27: 2 | E27: 2 | F27: 3.7 | H27: =SUM(C27:F27) -> 10.6
A28: 45883 | B28: Morning | C28: 4.4 | D28: 2 | E28: 2.2 | F28: 4.7 | H28: =SUM(C28:F28) -> 13.3 | I28: =H28+H29 -> 24.2
B29: Evening | C29: 2.5 | D29: 2 | E29: 2 | F29: 4.4 | H29: =SUM(C29:F29) -> 10.9
A30: 45884 | B30: Morning | C30: 4 | D30: 2 | E30: 1.5 | F30: 4.5 | H30: =SUM(C30:F30) -> 12 | I30: =H30+H31 -> 22.6
B31: Evening | C31: 3.1 | D31: 2 | E31: 2 | F31: 3.5 | H31: =SUM(C31:F31) -> 10.6
A32: 45885 | B32: Morning | C32: 4 | D32: 2 | E32: 2.4 | F32: 4 | H32: =SUM(C32:F32) -> 12.4 | I32: =H32+H33 -> 22.7
B33: Evening | C33: 2.4 | D33: 2 | E33: 2.4 | F33: 3.5 | H33: =SUM(C33:F33) -> 10.3
A34: 45886 | B34: Morning | C34: 5 | D34: 2.2 | E34: 2.5 | F34: 4 | H34: =SUM(C34:F34) -> 13.7 | I34: =H34+H35 -> 23.4
B35: Evening | C35: 2.7 | D35: 2 | E35: 2 | F35: 3 | H35: =SUM(C35:F35) -> 9.7
A36: 45887 | B36: Morning | C36: 4.5 | D36: 2.3 | E36: 2.2 | F36: 4.7 | H36: =SUM(C36:F36) -> 13.7 | I36: =H36+H37 -> 24.2
B37: Evening | C37: 3 | D37: 1.5 | E37: 2 | F37: 4 | H37: =SUM(C37:F37) -> 10.5
A38: 45888 | B38: Morning | C38: 4.9 | D38: 2 | E38: 2 | F38: 5 | H38: =SUM(C38:F38) -> 13.9 | I38: =H38+H39 -> 22.6
B39: Evening | C39: 3 | D39: 2 | F39: 3.7 | H39: =SUM(C39:F39) -> 8.7
A40: 45889 | B40: Morning | C40: 0.5 | D40: 1.5 | E40: 2.6 | F40: 4.7 | H40: =SUM(C40:F40) -> 9.3 | I40: =H40+H41 -> 20.9
...

Sheet Sheet3

Sheet August Summary
A1: Cow Name | B1: Total Milk (Litres)
A2: Total | B2: =Sum(B3:B12) -> 701.1
A4: Shobha | B4: =SUM(August!C2:C63) -> 216.7
A5: Devaki | B5: =SUM(August!D2:D63) -> 93.1
A6: Sita | B6: =SUM(August!E2:E63) -> 144
A7: Lakshmi | B7: =sum(August!F2:F63) -> 247.3
A8: Mruga

Sheet September 
A1: Date | B1: Milking | C1: Shobha | D1: Devaki | E1: Sita | F1: Lakshmi | H1: Total (Litres) | I1: Daily total (Litres)
A2: 45901 | B2: Morning | C2: 4.3 | D2: 0.7 | E2: 3.2 | F2: 3 | H2: =SUM(C2:F2) -> 11.2 | I2: =H2+H3 -> 19.2
B3: Evening | C3: 3.2 | E3: 2.4 | F3: 2.4 | H3: =SUM(C3:F3) -> 8
A4: 45902 | B4: Morning | C4: 4.5 | D4: 0 | E4: 3 | F4: 3 | H4: =SUM(C4:F4) -> 10.5 | I4: =H4+H5 -> 18.3
B5: Evening | C5: 2 | D5: 0 | E5: 2.8 | F5: 3 | H5: =SUM(C5:F5) -> 7.8
A6: 45903 | B6: Morning | C6: 4.5 | D6: 0 | E6: 3 | F6: 3.5 | H6: =SUM(C6:F6) -> 11 | I6: =H6+H7 -> 19.2
B7: Evening | C7: 2.5 | D7: 0 | E7: 3 | F7: 2.7 | H7: =SUM(C7:F7) -> 8.2
A8: 45904 | B8: Morning | C8: 3.5 | D8: 0.5 | E8: 3.5 | F8: 2.5 | H8: =SUM(C8:F8) -> 10 | I8: =H8+H9 -> 18.3
B9: Evening | C9: 2.5 | D9: 0 | E9: 2.8 | F9: 3 | H9: =SUM(C9:F9) -> 8.3
A10: 45905 | B10: Morning | C10: 3.1 | D10: 0 | E10: 3.2 | F10: 3.8 | H10: =SUM(C10:F10) -> 10.1 | I10: =H10+H11 -> 18.4
B11: Evening | C11: 2.6 | D11: 0 | E11: 2.7 | F11: 3 | H11: =SUM(C11:F11) -> 8.3
A12: 45906 | B12: Morning | C12: 3.7 | D12: 0 | E12: 3 | F12: 3 | H12: =SUM(C12:F12) -> 9.7 | I12: =H12+H13 -> 18.4
B13: Evening | C13: 2.5 | D13: 0 | E13: 3 | F13: 3.2 | H13: =SUM(C13:F13) -> 8.7
A14: 45907 | B14: Morning | C14: 3.5 | D14: 0 | E14: 3 | F14: 3.5 | H14: =SUM(C14:F14) -> 10 | I14: =H14+H15 -> 19.3
B15: Evening | C15: 3 | D15: 0.5 | E15: 2.9 | F15: 2.9 | H15: =SUM(C15:F15) -> 9.3
A16: 45908 | B16: Morning | C16: 3.7 | D16: 0 | E16: 3 | F16: 3.5 | H16: =SUM(C16:F16) -> 10.2 | I16: =H16+H17 -> 19.2
B17: Evening | C17: 3 | D17: 0 | E17: 3 | F17: 3 | H17: =SUM(C17:F17) -> 9
A18: 45909 | B18: Morning | C18: 3.5 | D18: 0 | E18: 3 | F18: 3.2 | H18: =SUM(C18:F18) -> 9.7 | I18: =H18+H19 -> 16.2
B19: Evening | C19: 1.5 | D19: 0 | E19: 2.5 | F19: 2.5 | H19: =SUM(C19:F19) -> 6.5
A20: 45910 | B20: Morning | C20: 4.4 | D20: 0 | E20: 3 | F20: 4 | H20: =SUM(C20:F20) -> 11.4 | I20: =H20+H21 -> 21.9
B21: Evening | C21: 3.5 | D21: 0 | E21: 3.5 | F21: 3.5 | H21: =SUM(C21:F21) -> 10.5
A22: 45911 | B22: Morning | C22: 3.9 | D22: 0 | E22: 3.5 | F22: 3.5 | H22: =SUM(C22:F22) -> 10.9 | I22: =H22+H23 -> 21.3
B23: Evening | C23: 3.4 | E23: 3 | F23: 4 | H23: =SUM(C23:F23) -> 10.4
A24: 45912 | B24: Morning | C24: 2.2 | E24: 3 | F24: 4 | H24: =SUM(C24:F24) -> 9.2 | I24: =H24+H25 -> 19.7
B25: Evening | C25: 3.5 | E25: 3 | F25: 4 | H25: =SUM(C25:F25) -> 10.5
A26: 45913 | B26: Morning | C26: 4 | E26: 3 | F26: 4 | H26: =SUM(C26:F26) -> 11 | I26: =H26+H27 -> 17.5
B27: Evening | C27: 1 | E27: 2 | F27: 3.5 | H27: =SUM(C27:F27) -> 6.5
A28: 45914 | B28: Morning | C28: 4 | E28: 3.5 | F28: 4.5 | H28: =SUM(C28:F28) -> 12 | I28: =H28+H29 -> 22.1
B29: Evening | C29: 3.5 | E29: 3.3 | F29: 3.3 | H29: =SUM(C29:F29) -> 10.1
A30: 45915 | B30: Morning | C30: 4 | E30: 3.5 | F30: 3.5 | H30: =SUM(C30:F30) -> 11 | I30: =H30+H31 -> 18.5
B31: Evening | C31: 2.5 | E31: 1.5 | F31: 3.5 | H31: =SUM(C31:F31) -> 7.5
A32: 45916 | B32: Morning | C32: 4.1 | E32: 2.6 | F32: 3.5 | H32: =SUM(C32:F32) -> 10.2 | I32: =H32+H33 -> 20.9
B33: Evening | C33: 3.5 | E33: 3.5 | F33: 3.7 | H33: =SUM(C33:F33) -> 10.7
A34: 45917 | B34: Morning | C34: 3.5 | E34: 1.5 | F34: 1 | H34: =SUM(C34:F34) -> 6 | I34: =H34+H35 -> 16
B35: Evening | C35: 4 | E35: 2.5 | F35: 3.5 | H35: =SUM(C35:F35) -> 10
A36: 45918 | B36: Morning | C36: 4.5 | E36: 2.2 | F36: 4 | H36: =SUM(C36:F36) -> 10.7 | I36: =H36+H37 -> 19.6
B37: Evening | C37: 3.5 | E37: 2.2 | F37: 3.2 | H37: =SUM(C37:F37) -> 8.9
A38: 45919 | B38: Morning | C38: 3.5 | E38: 1.7 | F38: 3.9 | H38: =SUM(C38:F38) -> 9.1 | I38: =H38+H39 -> 18
B39: Evening | C39: 4 | E39: 1.9 | F39: 3 | H39: =SUM(C39:F39) -> 8.9
A40: 45920 | B40: Morning | C40: 3.2 | E40: 1.2 | F40: 3.4 | H40: =SUM(C40:F40) -> 7.8 | I40: =H40+H41 -> 16.6
...

Sheet September Summary
A1: Cow Name | B1: Total Milk (Litres)
A2: Total | B2: =Sum(B3:B12) -> 539.1
A4: Shobha | B4: =sum('September '!C2:C63) -> 203.4
A5: Devaki | B5: =sum('September '!D2:D63) -> 1.7
A6: Sita | B6: =sum('September '!E2:E63) -> 141.2
A7: Lakshmi | B7: =sum('September '!F2:F63) -> 192.8
A8: Mruga

Sheet October 
A1: Date | B1: Milking | C1: Shobha | D1: Devaki | E1: Sita | F1: Lakshmi | G1: Mruga | H1: Total (Litres) | I1: Daily total (Litres)
A2: 45931 | B2: Morning | C2: 4 | E2: 1.8 | F2: 3 | H2: =SUM(C2:G2) -> 8.8 | I2: =H2+H3 -> 15.6
B3: Evening | C3: 3.3 | E3: 1 | F3: 2.5 | H3: =SUM(C3:G3) -> 6.8
A4: 45932 | B4: Morning | C4: 3.5 | E4: 1 | F4: 2.5 | H4: =SUM(C4:G4) -> 7 | I4: =H4+H5 -> 15
B5: Evening | C5: 4 | E5: 1.3 | F5: 2.7 | H5: =SUM(C5:G5) -> 8
A6: 45933 | B6: Morning | C6: 3.5 | E6: 1.2 | F6: 2.5 | H6: =SUM(C6:G6) -> 7.2 | I6: =H6+H7 -> 12.7
B7: Evening | C7: 3.5 | E7: 0 | F7: 2 | H7: =SUM(C7:G7) -> 5.5
A8: 45934 | B8: Morning | C8: 4 | E8: 0 | F8: 4 | H8: =SUM(C8:G8) -> 8 | I8: =H8+H9 -> 15.5
B9: Evening | C9: 3.5 | E9: 1.5 | F9: 2.5 | H9: =SUM(C9:G9) -> 7.5
A10: 45935 | B10: Morning | C10: 3.5 | E10: 2.2 | F10: 2.2 | H10: =SUM(C10:G10) -> 7.9 | I10: =H10+H11 -> 16
B11: Evening | C11: 3.5 | E11: 1.8 | F11: 2.8 | H11: =SUM(C11:G11) -> 8.1
A12: 45936 | B12: Morning | C12: 4 | E12: 2.4 | F12: 3 | H12: =SUM(C12:F12) -> 9.4 | I12: =H12+H13 -> 16.8
B13: Evening | C13: 3 | E13: 1.7 | F13: 2.7 | H13: =SUM(C13:F13) -> 7.4
A14: 45937 | B14: Morning | C14: 4.3 | E14: 1.5 | F14: 3.7 | H14: =SUM(C14:F14) -> 9.5 | I14: =H14+H15 -> 16.4
B15: Evening | C15: 3 | E15: 1.2 | F15: 2.7 | H15: =SUM(C15:F15) -> 6.9
A16: 45938 | B16: Morning | C16: 3.5 | E16: 1.6 | F16: 3.5 | H16: =SUM(C16:F16) -> 8.6 | I16: =H16+H17 -> 16.4
B17: Evening | C17: 3 | E17: 1.3 | F17: 3.5 | H17: =SUM(C17:F17) -> 7.8
A18: 45939 | B18: Morning | C18: 3.5 | E18: 2.3 | F18: 3.5 | H18: =SUM(C18:F18) -> 9.3 | I18: =H18+H19 -> 14.9
B19: Evening | C19: 2.2 | E19: 1.2 | F19: 2.2 | H19: =SUM(C19:F19) -> 5.6
A20: 45940 | B20: Morning | C20: 3.5 | E20: 1 | F20: 3 | H20: =SUM(C20:F20) -> 7.5 | I20: =H20+H21 -> 14.8
B21: Evening | C21: 3.2 | E21: 1.5 | F21: 2.6 | H21: =SUM(C21:F21) -> 7.3
A22: 45941 | B22: Morning | C22: 0 | E22: 0.7 | F22: 3.5 | H22: =SUM(C22:F22) -> 4.2 | I22: =H22+H23 -> 11.7
B23: Evening | C23: 3 | E23: 1.5 | F23: 3 | H23: =SUM(C23:F23) -> 7.5
A24: 45942 | B24: Morning | C24: 4 | E24: 1.3 | F24: 2.9 | H24: =SUM(C24:F24) -> 8.2 | I24: =H24+H25 -> 14.9
B25: Evening | C25: 3 | E25: 0.8 | F25: 2.9 | H25: =SUM(C25:F25) -> 6.7
A26: 45943 | B26: Morning | C26: 3 | E26: 1.5 | F26: 2.5 | H26: =SUM(C26:F26) -> 7 | I26: =H26+H27 -> 11.2
B27: Evening | C27: 2.2 | E27: 1 | F27: 1 | H27: =SUM(C27:F27) -> 4.2
A28: 45944 | B28: Morning | C28: 3.5 | E28: 2 | F28: 2 | H28: =SUM(C28:F28) -> 7.5 | I28: =H28+H29 -> 14.3
B29: Evening | C29: 1.2 | E29: 2.4 | F29: 3.2 | H29: =SUM(C29:F29) -> 6.8
A30: 45945 | B30: Morning | C30: 3.5 | E30: 2.8 | F30: 2.5 | H30: =SUM(C30:F30) -> 8.8 | I30: =H30+H31 -> 16.2
B31: Evening | C31: 3 | E31: 2 | F31: 2.4 | H31: =SUM(C31:F31) -> 7.4
A32: 45946 | B32: Morning | C32: 3.5 | E32: 2 | F32: 3.5 | H32: =SUM(C32:F32) -> 9 | I32: =H32+H33 -> 16.6
B33: Evening | C33: 3 | E33: 2 | F33: 2.6 | H33: =SUM(C33:F33) -> 7.6
A34: 45947 | B34: Morning | C34: 4 | E34: 1.5 | F34: 2.7 | H34: =SUM(C34:F34) -> 8.2 | I34: =H34+H35 -> 14.6
B35: Evening | C35: 3 | E35: 1.5 | F35: 1.9 | H35: =SUM(C35:F35) -> 6.4
A36: 45948 | B36: Morning | C36: 3 | E36: 1.5 | F36: 2.5 | H36: =SUM(C36:F36) -> 7 | I36: =H36+H37 -> 14.2
B37: Evening | C37: 3.2 | E37: 1.5 | F37: 2.5 | H37: =SUM(C37:F37) -> 7.2
A38: 45949 | B38: Morning | C38: 4 | E38: 2.5 | F38: 2.5 | H38: =SUM(C38:F38) -> 9 | I38: =H38+H39 -> 15.4
B39: Evening | C39: 2.5 | E39: 1.7 | F39: 2.2 | H39: =SUM(C39:F39) -> 6.4
A40: 45950 | B40: Morning | C40: 4 | E40: 0 | F40: 3 | H40: =SUM(C40:F40) -> 7 | I40: =H40+H41 -> 10.9
...

Sheet October Summary
A1: Cow Name | B1: Total Milk (Litres)
A2: Total | B2: =Sum(B3:B12) -> 533.8
A4: Shobha | B4: =sum('October '!C2:C63) -> 182.7
A5: Devaki | B5: =sum('October '!D3:D63) -> 0
A6: Sita | B6: =sum('October '!E2:E63) -> 99.6
A7: Lakshmi | B7: =sum('October '!F2:F63) -> 181.1
A8: Mruga | B8: =sum('October '!G2:G63) -> 70.4

Sheet  November 
A1: Date | B1: Milking | C1: Shobha | D1: Devaki | E1: Sita | F1: Lakshmi | G1: Mruga | H1: Radha | I1: Pushpa | J1: Total (Litres) | K1: Daily total (Litres)
A2: 45962 | B2: Morning | C2: 2 | E2: 0 | F2: 3.5 | G2: 4.4 | J2: =SUM(C2:I2) -> 9.9 | K2: =J2+J3 -> 20.7
B3: Evening | C3: 3.8 | E3: 0 | F3: 3 | G3: 4 | J3: =SUM(C3:I3) -> 10.8
A4: 45963 | B4: Morning | C4: 3.3 | E4: 0 | F4: 3 | G4: 4.4 | J4: =SUM(C4:I4) -> 10.7 | K4: =J4+J5 -> 16.7
B5: Evening | C5: 0.5 | E5: 0.5 | F5: 2.5 | G5: 2.5 | J5: =SUM(C5:I5) -> 6
A6: 45964 | B6: Morning | C6: 3.3 | E6: 0 | F6: 3.5 | G6: 4.5 | J6: =SUM(C6:I6) -> 11.3 | K6: =J6+J7 -> 19.3
B7: Evening | C7: 3 | E7: 0.5 | F7: 1.5 | G7: 3 | J7: =SUM(C7:I7) -> 8
A8: 45965 | B8: Morning | C8: 2 | E8: 0 | F8: 0 | G8: 4 | J8: =SUM(C8:I8) -> 6 | K8: =J8+J9 -> 14.8
B9: Evening | C9: 2.5 | E9: 0 | F9: 2 | G9: 4.3 | J9: =SUM(C9:I9) -> 8.8
A10: 45966 | B10: Morning | C10: 3 | E10: 1 | F10: 4 | G10: 5 | J10: =SUM(C10:I10) -> 13 | K10: =J10+J11 -> 24
B11: Evening | C11: 2.5 | E11: 1.5 | F11: 3 | G11: 4 | J11: =SUM(C11:I11) -> 11
A12: 45967 | B12: Morning | C12: 3.5 | E12: 0.5 | F12: 4.5 | G12: 4.5 | J12: =SUM(C12:I12) -> 13 | K12: =J12+J13 -> 22.5
B13: Evening | C13: 2.5 | E13: 0 | F13: 3 | G13: 4 | J13: =SUM(C13:I13) -> 9.5
A14: 45968 | B14: Morning | C14: 0 | E14: 0 | F14: 4.5 | G14: 4.5 | J14: =SUM(C14:I14) -> 9 | K14: =J14+J15 -> 17.9
B15: Evening | C15: 3 | F15: 2.2 | G15: 3.7 | J15: =SUM(C15:I15) -> 8.9
A16: 45969 | B16: Morning | C16: 0 | F16: 3.3 | G16: 5 | J16: =SUM(C16:I16) -> 8.3 | K16: =J16+J17 -> 14.3
B17: Evening | F17: 2 | G17: 4 | J17: =SUM(C17:I17) -> 6
A18: 45970 | B18: Morning | C18: 3.7 | F18: 3.2 | G18: 4.5 | J18: =SUM(C18:I18) -> 11.4 | K18: =J18+J19 -> 19.2
B19: Evening | F19: 3.3 | G19: 4.5 | J19: =SUM(C19:I19) -> 7.8
A20: 45971 | B20: Morning | C20: 3.5 | F20: 3.5 | G20: 4.8 | J20: =SUM(C20:I20) -> 11.8 | K20: =J20+J21 -> 18.1
B21: Evening | F21: 3.5 | G21: 2.8 | J21: =SUM(C21:I21) -> 6.3
A22: 45972 | B22: Morning | C22: 3 | F22: 3.5 | G22: 1.5 | J22: =SUM(C22:I22) -> 8 | K22: =J22+J23 -> 16
B23: Evening | C23: 1.5 | F23: 3 | G23: 3.5 | J23: =SUM(C23:I23) -> 8
A24: 45973 | B24: Morning | C24: 2.5 | F24: 3.5 | G24: 4.7 | J24: =SUM(C24:I24) -> 10.7 | K24: =J24+J25 -> 17.4
B25: Evening | F25: 3.3 | G25: 3.4 | J25: =SUM(C25:I25) -> 6.7
A26: 45974 | B26: Morning | C26: 3.7 | F26: 3.9 | G26: 5 | J26: =SUM(C26:I26) -> 12.6 | K26: =J26+J27 -> 20.1
B27: Evening | F27: 3.5 | G27: 4 | J27: =SUM(C27:I27) -> 7.5
A28: 45975 | B28: Morning | C28: 3.5 | F28: 3.5 | G28: 5.5 | J28: =SUM(C28:I28) -> 12.5 | K28: =J28+J29 -> 20
B29: Evening | F29: 2.5 | G29: 5 | J29: =SUM(C29:I29) -> 7.5
A30: 45976 | B30: Morning | F30: 2.5 | G30: 5 | J30: =SUM(C30:I30) -> 7.5 | K30: =J30+J31 -> 20.5
B31: Evening | C31: 3 | F31: 2 | G31: 4.5 | H31: 3.5 | J31: =SUM(C31:I31) -> 13
A32: 45977 | B32: Morning | C32: 3 | F32: 3 | G32: 4.5 | H32: 3.5 | J32: =SUM(C32:I32) -> 14 | K32: =J32+J33 -> 24.5
B33: Evening | F33: 3 | G33: 4 | H33: 3.5 | J33: =SUM(C33:I33) -> 10.5
A34: 45978 | B34: Morning | C34: 2 | F34: 3 | G34: 4.5 | H34: 3.5 | J34: =SUM(C34:I34) -> 13 | K34: =J34+J35 -> 23.3
B35: Evening | F35: 2.5 | G35: 4.3 | H35: 3.5 | J35: =SUM(C35:I35) -> 10.3
A36: 45979 | B36: Morning | F36: 3 | G36: 4 | H36: 3.5 | J36: =SUM(C36:I36) -> 10.5 | K36: =J36+J37 -> 20.7
B37: Evening | F37: 3 | G37: 3.7 | H37: 3.5 | J37: =SUM(C37:I37) -> 10.2
A38: 45980 | B38: Morning | C38: 2.5 | F38: 3.5 | G38: 3.7 | H38: 4 | J38: =SUM(C38:I38) -> 13.7 | K38: =J38+J39 -> 22.6
B39: Evening | F39: 2.4 | G39: 3.5 | H39: 3 | J39: =SUM(C39:I39) -> 8.9
A40: 45981 | B40: Morning | C40: 2.5 | F40: 3.5 | G40: 4.8 | H40: 3.5 | J40: =SUM(C40:I40) -> 14.3 | K40: =J40+J41 -> 24.8
...

Sheet November Summary
A1: Cow Name | B1: Total Milk (Litres)
A2: Total | B2: =Sum(B3:B12) -> 602.2
A4: Shobha | B4: =sum(' November '!C2:C63) -> 92.6
A5: Devaki | B5: =sum(' November '!D2:D62) -> 0
A6: Sita | B6: =sum(' November '!E2:E63) -> 4
A7: Lakshmi | B7: =sum(' November '!F2:F63) -> 166.5
A8: Mruga | B8: =sum(' November '!G2:G63) -> 237.9
A9: Radha | B9: =sum(' November '!H2:H63) -> 81.4
A10: Pushpa | B10: =sum(' November '!I3:I64) -> 19.8

Sheet December
A1: Date | B1: Milking | C1: Shobha | D1: Devaki | E1: Sita | F1: Lakshmi | G1: Mruga | H1: Radha | I1: Shravani | J1: Total (Litres) | K1: Daily total (Litres) | M1: Transfer to milk sale | N1: Transfer to ghee | O1: Balance milk
A2: 45992 | B2: Morning | C2: 1.5 | F2: 3 | G2: 3.8 | H2: 3 | I2: 3 | J2: =SUM(C2:I2) -> 14.3 | K2: =J2+J3 -> 24.6 | O2: =J2-M2-N2 -> 14.3
B3: Evening | F3: 3 | G3: 3.8 | H3: 1.5 | I3: 2 | J3: =SUM(C3:I3) -> 10.3 | M3: 0 | O3: =J3-M3-N3 -> 10.3
A4: 45993 | B4: Morning | C4: 1.5 | F4: 3.4 | G4: 3.7 | H4: 4.4 | I4: 3.3 | J4: =SUM(C4:I4) -> 16.3 | K4: =J4+J5 -> 26.7 | O4: =J4-M4-N4 -> 16.3
B5: Evening | F5: 3 | G5: 4 | H5: 1.4 | I5: 2 | J5: =SUM(C5:I5) -> 10.4 | O5: =J5-M5-N5 -> 10.4
A6: 45994 | B6: Morning | C6: 2 | F6: 3.3 | G6: 4 | H6: 5 | I6: 4.5 | J6: =SUM(C6:I6) -> 18.8 | K6: =J6+J7 -> 27.8 | O6: =J6-M6-N6 -> 18.8
B7: Evening | F7: 2 | G7: 3.5 | H7: 1 | I7: 2.5 | J7: =SUM(C7:I7) -> 9 | O7: =J7-M7-N7 -> 9
A8: 45995 | B8: Morning | C8: 2 | F8: 2 | G8: 4 | H8: 2 | I8: 3 | J8: =SUM(C8:I8) -> 13 | K8: =J8+J9 -> 23.7 | O8: =J8-M8-N8 -> 13
B9: Evening | F9: 1.8 | G9: 3.4 | H9: 2.5 | I9: 3 | J9: =SUM(C9:I9) -> 10.7 | O9: =J9-M9-N9 -> 10.7
A10: 45996 | B10: Morning | C10: 2 | F10: 2.5 | G10: 3.7 | H10: 1.8 | I10: 4 | J10: =SUM(C10:I10) -> 14 | K10: =J10+J11 -> 23.2 | O10: =J10-M10-N10 -> 14
B11: Evening | F11: 2 | G11: 2.7 | H11: 2 | I11: 2.5 | J11: =SUM(C11:I11) -> 9.2 | O11: =J11-M11-N11 -> 9.2
A12: 45997 | B12: Morning | C12: 2 | F12: 2.5 | G12: 3.7 | H12: 2 | I12: 4 | J12: =SUM(C12:I12) -> 14.2 | K12: =J12+J13 -> 22.8 | O12: =J12-M12-N12 -> 14.2
B13: Evening | F13: 1.5 | G13: 2.6 | H13: 2 | I13: 2.5 | J13: =SUM(C13:I13) -> 8.6 | O13: =J13-M13-N13 -> 8.6
A14: 45998 | B14: Morning | C14: 1.8 | F14: 2.5 | G14: 3.5 | H14: 2 | I14: 3.5 | J14: =SUM(C14:I14) -> 13.3 | K14: =J14+J15 -> 22.8 | O14: =J14-M14-N14 -> 13.3
B15: Evening | F15: 2.3 | G15: 3.7 | I15: 3.5 | J15: =SUM(C15:I15) -> 9.5 | O15: =J15-M15-N15 -> 9.5
A16: 45999 | B16: Morning | C16: 2 | F16: 3 | G16: 3.5 | H16: 3.5 | I16: 4 | J16: =SUM(C16:I16) -> 16 | K16: =J16+J17 -> 26.4 | O16: =J16-M16-N16 -> 16
B17: Evening | F17: 2.2 | G17: 3.2 | H17: 1.5 | I17: 3.5 | J17: =SUM(C17:I17) -> 10.4 | O17: =J17-M17-N17 -> 10.4
A18: 46000 | B18: Morning | C18: 1.5 | F18: 2.5 | G18: 4 | H18: 2 | I18: 4 | J18: =SUM(C18:I18) -> 14 | K18: =J18+J19 -> 23.2 | O18: =J18-M18-N18 -> 14
B19: Evening | F19: 2.3 | G19: 3.4 | I19: 3.5 | J19: =SUM(C19:I19) -> 9.2 | O19: =J19-M19-N19 -> 9.2
A20: 46001 | B20: Morning | C20: 1.5 | F20: 2.6 | G20: 3.3 | H20: 3 | I20: 4.5 | J20: =SUM(C20:I20) -> 14.9 | K20: =J20+J21 -> 24.2 | O20: =J20-M20-N20 -> 14.9
B21: Evening | F21: 2.3 | G21: 3.5 | H21: 1.5 | I21: 2 | J21: =SUM(C21:I21) -> 9.3 | O21: =J21-M21-N21 -> 9.3
A22: 46002 | B22: Morning | C22: 1.5 | F22: 3 | G22: 3.5 | H22: 3.5 | I22: 4 | J22: =SUM(C22:I22) -> 15.5 | K22: =J22+J23 -> 23.2 | O22: =J22-M22-N22 -> 15.5
B23: Evening | F23: 1.5 | G23: 2.5 | H23: 0.7 | I23: 3 | J23: =SUM(C23:I23) -> 7.7 | O23: =J23-M23-N23 -> 7.7
A24: 46003 | B24: Morning | C24: 1.5 | F24: 3 | G24: 2.8 | H24: 2.7 | I24: 3.5 | J24: =SUM(C24:I24) -> 13.5 | K24: =J24+J25 -> 24.4 | O24: =J24-M24-N24 -> 13.5
B25: Evening | F25: 2.5 | G25: 3.4 | H25: 2.5 | I25: 2.5 | J25: =SUM(C25:I25) -> 10.9 | O25: =J25-M25-N25 -> 10.9
A26: 46004 | B26: Morning | F26: 2 | G26: 2.6 | H26: 1 | I26: 3 | J26: =SUM(C26:I26) -> 8.6 | K26: =J26+J27 -> 17 | O26: =J26-M26-N26 -> 8.6
B27: Evening | F27: 2 | G27: 2.9 | H27: 0.5 | I27: 3 | J27: =SUM(C27:I27) -> 8.4 | O27: =J27-M27-N27 -> 8.4
A28: 46005 | B28: Morning | C28: 2.1 | F28: 2.1 | G28: 3 | H28: 3.1 | I28: 3.5 | J28: =SUM(C28:I28) -> 13.8 | K28: =J28+J29 -> 22.3 | O28: =J28-M28-N28 -> 13.8
B29: Evening | F29: 2 | G29: 2.5 | H29: 1.5 | I29: 2.5 | J29: =SUM(C29:I29) -> 8.5 | O29: =J29-M29-N29 -> 8.5
A30: 46006 | B30: Morning | C30: 1.5 | F30: 2.5 | G30: 3.5 | H30: 2.2 | I30: 3.5 | J30: =SUM(C30:I30) -> 13.2 | K30: =J30+J31 -> 23.2 | O30: =J30-M30-N30 -> 13.2
B31: Evening | F31: 2.5 | G31: 3 | H31: 2 | I31: 2.5 | J31: =SUM(C31:I31) -> 10 | O31: =J31-M31-N31 -> 10
A32: 46007 | B32: Morning | C32: 1.5 | F32: 2.5 | G32: 3.7 | H32: 1.5 | I32: 4 | J32: =SUM(C32:I32) -> 13.2 | K32: =J32+J33 -> 25.2 | M32: 7 | O32: =J32-M32-N32 -> 6.2
B33: Evening | F33: 1.8 | G33: 3 | H33: 4.5 | I33: 2.7 | J33: =SUM(C33:I33) -> 12 | O33: =J33-M33-N33 -> 12
A34: 46008 | B34: Morning | C34: 1.5 | F34: 2.5 | G34: 2.7 | H34: 1.5 | I34: 3.5 | J34: =SUM(C34:I34) -> 11.7 | K34: =J34+J35 -> 22 | O34: =J34-M34-N34 -> 11.7
B35: Evening | F35: 2.5 | G35: 3.8 | H35: 1.5 | I35: 2.5 | J35: =SUM(C35:I35) -> 10.3 | O35: =J35-M35-N35 -> 10.3
A36: 46009 | B36: Morning | C36: 1.7 | F36: 3 | G36: 3.5 | H36: 3 | I36: 4 | J36: =SUM(C36:I36) -> 15.2 | K36: =J36+J37 -> 25.1 | O36: =J36-M36-N36 -> 15.2
B37: Evening | F37: 3 | G37: 3.4 | H37: 2 | I37: 1.5 | J37: =SUM(C37:I37) -> 9.9 | O37: =J37-M37-N37 -> 9.9
A38: 46010 | B38: Morning | C38: 1.5 | F38: 2.6 | G38: 4 | H38: 4 | I38: 4 | J38: =SUM(C38:I38) -> 16.1 | K38: =J38+J39 -> 24.8 | O38: =J38-M38-N38 -> 16.1
B39: Evening | F39: 1.5 | G39: 2.7 | H39: 1.5 | I39: 3 | J39: =SUM(C39:I39) -> 8.7 | O39: =J39-M39-N39 -> 8.7
A40: 46011 | B40: Morning | C40: 1.5 | F40: 3 | G40: 4 | H40: 2 | I40: 2.5 | J40: =SUM(C40:I40) -> 13 | K40: =J40+J41 -> 20 | O40: =J40-M40-N40 -> 13
...

Sheet December Summary
A1: Cow Name | B1: Total Milk (Litres)
A2: Total | B2: =Sum(B3:B12) -> 746.3
A4: Shobha | B4: =sum(December!C2:C63) -> 44.1
A5: Devaki | B5: =sum(December!D2:D63) -> 0
A6: Sita | B6: =sum(December!E2:E63) -> 0
A7: Lakshmi | B7: =sum(December!F2:F63) -> 173.2
A8: Mruga | B8: =sum(December!G2:G63) -> 220.3
A9: Radha | B9: =sum(December!H2:H63) -> 114.4
A10: Shravani | B10: =sum(December!I2:I64) -> 194.3

Sheet January 2026
A1: Date | B1: Milking | C1: Shobha | D1: Devaki | E1: Sita | F1: Lakshmi | G1: Mruga | H1: Radha | I1: Shravani | J1: Total (Litres) | K1: Daily total (Litres) | M1: Transfer to milk sale | N1: Transfer to ghee | O1: Balance milk
A2: 45992 | B2: Morning | C2: 1.5 | F2: 3.5 | G2: 5.5 | H2: 4.5 | I2: 3.5 | J2: =SUM(C2:I2) -> 18.5 | K2: =J2+J3 -> 26.5 | O2: =J2-M2-N2 -> 18.5
B3: Evening | F3: 2.5 | G3: 2.5 | I3: 3 | J3: =SUM(C3:I3) -> 8 | M3: 0 | O3: =J3-M3-N3 -> 8
A4: 45993 | B4: Morning | C4: 1.5 | F4: 4.5 | G4: 5.3 | H4: 4 | I4: 4 | J4: =SUM(C4:I4) -> 19.3 | K4: =J4+J5 -> 28.6 | O4: =J4-M4-N4 -> 19.3
B5: Evening | F5: 2.3 | G5: 4 | I5: 3 | J5: =SUM(C5:I5) -> 9.3 | O5: =J5-M5-N5 -> 9.3
A6: 45994 | B6: Morning | C6: 1.5 | F6: 4.5 | G6: 4.5 | H6: 4.4 | I6: 4 | J6: =SUM(C6:I6) -> 18.9 | K6: =J6+J7 -> 33.6 | O6: =J6-M6-N6 -> 18.9
B7: Evening | F7: 2.5 | G7: 4 | H7: 5.2 | I7: 3 | J7: =SUM(C7:I7) -> 14.7 | O7: =J7-M7-N7 -> 14.7
A8: 45995 | B8: Morning | C8: 1.5 | F8: 4.5 | G8: 4.2 | H8: 4.4 | I8: 4 | J8: =SUM(C8:I8) -> 18.6 | K8: =J8+J9 -> 29.5 | O8: =J8-M8-N8 -> 18.6
B9: Evening | F9: 3.2 | G9: 4.5 | I9: 3.2 | J9: =SUM(C9:I9) -> 10.9 | O9: =J9-M9-N9 -> 10.9
A10: 45996 | B10: Morning | C10: 1.5 | F10: 4 | G10: 4.6 | H10: 6 | I10: 4.5 | J10: =SUM(C10:I10) -> 20.6 | K10: =J10+J11 -> 31.7 | O10: =J10-M10-N10 -> 20.6
B11: Evening | F11: 3.8 | G11: 3.5 | I11: 3.8 | J11: =SUM(C11:I11) -> 11.1 | O11: =J11-M11-N11 -> 11.1
A12: 45997 | B12: Morning | F12: 4.5 | G12: 4.5 | H12: 3.9 | I12: 4 | J12: =SUM(C12:I12) -> 16.9 | K12: =J12+J13 -> 25.4 | O12: =J12-M12-N12 -> 16.9
B13: Evening | F13: 3.5 | G13: 1 | I13: 4 | J13: =SUM(C13:I13) -> 8.5 | O13: =J13-M13-N13 -> 8.5
A14: 45998 | B14: Morning | C14: 2 | F14: 4 | G14: 4.5 | H14: 5.5 | I14: 4 | J14: =SUM(C14:I14) -> 20 | K14: =J14+J15 -> 31 | O14: =J14-M14-N14 -> 20
B15: Evening | F15: 3 | G15: 4 | I15: 4 | J15: =SUM(C15:I15) -> 11 | O15: =J15-M15-N15 -> 11
A16: 45999 | B16: Morning | C16: 0.5 | F16: 4 | G16: 5 | H16: 4 | I16: 4 | J16: =SUM(C16:I16) -> 17.5 | K16: =J16+J17 -> 31 | O16: =J16-M16-N16 -> 17.5
B17: Evening | F17: 4 | G17: 4 | H17: 1.5 | I17: 4 | J17: =SUM(C17:I17) -> 13.5 | O17: =J17-M17-N17 -> 13.5
A18: 46000 | B18: Morning | C18: 1 | F18: 4 | G18: 5 | H18: 5 | I18: 4 | J18: =SUM(C18:I18) -> 19 | K18: =J18+J19 -> 31 | O18: =J18-M18-N18 -> 19
B19: Evening | F19: 4.5 | G19: 4.5 | H19: 1 | I19: 2 | J19: =SUM(C19:I19) -> 12 | O19: =J19-M19-N19 -> 12
A20: 46001 | B20: Morning | C20: 1.4 | F20: 4 | G20: 5.8 | H20: 3.5 | I20: 6.5 | J20: =SUM(C20:I20) -> 21.2 | K20: =J20+J21 -> 32.7 | O20: =J20-M20-N20 -> 21.2
B21: Evening | F21: 3.5 | G21: 4 | I21: 4 | J21: =SUM(C21:I21) -> 11.5 | O21: =J21-M21-N21 -> 11.5
A22: 46002 | B22: Morning | C22: 2 | F22: 4 | G22: 4.5 | H22: 5.5 | I22: 4 | J22: =SUM(C22:I22) -> 20 | K22: =J22+J23 -> 32 | O22: =J22-M22-N22 -> 20
B23: Evening | F23: 3.5 | G23: 5 | I23: 3.5 | J23: =SUM(C23:I23) -> 12 | O23: =J23-M23-N23 -> 12
A24: 46003 | B24: Morning | C24: 1.2 | F24: 4.5 | G24: 4.8 | H24: 5 | I24: 5 | J24: =SUM(C24:I24) -> 20.5 | K24: =J24+J25 -> 34 | O24: =J24-M24-N24 -> 20.5
B25: Evening | F25: 3.5 | G25: 5 | I25: 5 | J25: =SUM(C25:I25) -> 13.5 | O25: =J25-M25-N25 -> 13.5
A26: 46004 | B26: Morning | C26: 1 | F26: 4.9 | G26: 4 | H26: 4.5 | I26: 6 | J26: =SUM(C26:I26) -> 20.4 | K26: =J26+J27 -> 39.6 | O26: =J26-M26-N26 -> 20.4
B27: Evening | F27: 4.2 | G27: 5 | H27: 5.2 | I27: 4.8 | J27: =SUM(C27:I27) -> 19.2 | O27: =J27-M27-N27 -> 19.2
A28: 46005 | B28: Morning | F28: 5 | G28: 5 | H28: 3.5 | I28: 5 | J28: =SUM(C28:I28) -> 18.5 | K28: =J28+J29 -> 34.7 | O28: =J28-M28-N28 -> 18.5
B29: Evening | F29: 4.5 | G29: 4.5 | H29: 2.2 | I29: 5 | J29: =SUM(C29:I29) -> 16.2 | O29: =J29-M29-N29 -> 16.2
A30: 46006 | B30: Morning | F30: 5 | G30: 5 | H30: 5 | I30: 5.4 | J30: =SUM(C30:I30) -> 20.4 | K30: =J30+J31 -> 35.1 | O30: =J30-M30-N30 -> 20.4
B31: Evening | F31: 4.5 | G31: 5.2 | H31: 2 | I31: 3 | J31: =SUM(C31:I31) -> 14.7 | O31: =J31-M31-N31 -> 14.7
A32: 46007 | B32: Morning | F32: 5.5 | G32: 4.8 | H32: 6 | I32: 4.5 | J32: =SUM(C32:I32) -> 20.8 | K32: =J32+J33 -> 34.3 | O32: =J32-M32-N32 -> 20.8
B33: Evening | F33: 5 | G33: 5 | I33: 3.5 | J33: =SUM(C33:I33) -> 13.5 | O33: =J33-M33-N33 -> 13.5
A34: 46008 | B34: Morning | F34: 5 | G34: 5 | H34: 7 | I34: 6 | J34: =SUM(C34:I34) -> 23 | K34: =J34+J35 -> 37 | O34: =J34-M34-N34 -> 23
B35: Evening | F35: 5 | G35: 4.5 | H35: 3.5 | I35: 1 | J35: =SUM(C35:I35) -> 14 | O35: =J35-M35-N35 -> 14
A36: 46009 | B36: Morning | F36: 5 | G36: 5 | H36: 5 | I36: 5.8 | J36: =SUM(C36:I36) -> 20.8 | K36: =J36+J37 -> 33.3 | O36: =J36-M36-N36 -> 20.8
B37: Evening | F37: 5 | G37: 4.5 | I37: 3 | J37: =SUM(C37:I37) -> 12.5 | O37: =J37-M37-N37 -> 12.5
A38: 46010 | B38: Morning | F38: 5 | G38: 4.5 | H38: 6.5 | I38: 3.5 | J38: =SUM(C38:I38) -> 19.5 | K38: =J38+J39 -> 31.7 | O38: =J38-M38-N38 -> 19.5
B39: Evening | F39: 5 | G39: 4.5 | I39: 2.7 | J39: =SUM(C39:I39) -> 12.2 | O39: =J39-M39-N39 -> 12.2
A40: 46011 | B40: Morning | F40: 5 | G40: 4.5 | H40: 8 | I40: 4 | J40: =SUM(C40:I40) -> 21.5 | K40: =J40+J41 -> 35.5 | O40: =J40-M40-N40 -> 21.5
...

Sheet January 26 Summary
A1: Cow Name | B1: Total Milk (Litres)
A2: Total | B2: =Sum(B3:B12) -> 1017
A4: Shobha | B4: =sum('January 2026'!C2:C63) -> 16.6
A5: Devaki | B5: =sum('January 2026'!D2:D63) -> 0
A6: Sita | B6: =sum('January 2026'!E2:E63) -> 0
A7: Lakshmi | B7: =sum('January 2026'!F2:F63) -> 272.3
A8: Mruga | B8: =sum('January 2026'!G2:G63) -> 289.7
A9: Radha | B9: =sum('January 2026'!H2:H63) -> 206.5
A10: Shravani | B10: =sum('January 2026'!I2:I63) -> 231.9

Sheet Feb 26 Summary
A1: Cow Name | B1: Total Milk (Litres)
A2: Total | B2: =Sum(B3:B13) -> 1032.3
A4: Shobha | B4: =sum('Feb 2026'!C2:C63) -> 0
A5: Devaki | B5: =sum('Feb 2026'!D2:D63) -> 0
A6: Sita | B6: =sum('Feb 2026'!E2:E63) -> 0
A7: Lakshmi | B7: =sum('Feb 2026'!F2:F63) -> 251
A8: Mruga | B8: =sum('Feb 2026'!G2:G63) -> 262.1
A9: Radha | B9: =sum('Feb 2026'!H2:H63) -> 183.6
A10: Shravani | B10: =sum('Feb 2026'!I2:I63) -> 18.7
A11: Uma | B11: =sum('Feb 2026'!J2:J63) -> 98.5
A12: Parvati | B12: =sum('Feb 2026'!K2:K63) -> 98.4
A13: Durga | B13: =sum('Feb 2026'!L2:L63) -> 120

Sheet Feb 2026
A1: Datemm- | B1: Milking | C1: Shobha | D1: Devaki | E1: Sita | F1: Lakshmi | G1: Mruga | H1: Radha | I1: Shravani | J1: Uma | K1: Parvati | L1: Durga | M1: Total (Litres) | N1: Daily total (Litres) | P1: Transfer to milk sale | Q1: Transfer to ghee | R1: Balance milk
A2: 46054 | B2: Morning | F2: 5 | G2: 5.5 | H2: 5.5 | M2: =SUM(C2:L2) -> 16 | N2: =M2+M3 -> 25 | R2: =M2-P2-Q2 -> 16
B3: Evening | F3: 3.5 | G3: 4.5 | H3: 1 | M3: =SUM(C3:L3) -> 9 | P3: 0 | R3: =M3-P3-Q3 -> 9
A4: 46055 | B4: Morning | F4: 4.7 | G4: 5 | H4: 5.5 | M4: =SUM(C4:L4) -> 15.2 | N4: =M4+M5 -> 25.7 | R4: =M4-P4-Q4 -> 15.2
B5: Evening | F5: 4.5 | G5: 5 | H5: 1 | M5: =SUM(C5:L5) -> 10.5 | R5: =M5-P5-Q5 -> 10.5
A6: 46056 | B6: Morning | F6: 4.5 | G6: 5 | H6: 4 | M6: =SUM(C6:L6) -> 13.5 | N6: =M6+M7 -> 28.7 | R6: =M6-P6-Q6 -> 13.5
B7: Evening | F7: 5.3 | G7: 5.4 | H7: 4.5 | M7: =SUM(C7:L7) -> 15.2 | R7: =M7-P7-Q7 -> 15.2
A8: 46057 | B8: Morning | F8: 4.5 | G8: 5.5 | H8: 5 | M8: =SUM(C8:L8) -> 15 | N8: =M8+M9 -> 26 | R8: =M8-P8-Q8 -> 15
B9: Evening | F9: 4 | G9: 5 | H9: 2 | M9: =SUM(C9:L9) -> 11 | R9: =M9-P9-Q9 -> 11
A10: 46058 | B10: Morning | F10: 5 | G10: 5.5 | H10: 6 | M10: =SUM(C10:L10) -> 16.5 | N10: =M10+M11 -> 27.5 | R10: =M10-P10-Q10 -> 16.5
B11: Evening | F11: 4 | G11: 5 | H11: 2 | M11: =SUM(C11:L11) -> 11 | R11: =M11-P11-Q11 -> 11
A12: 46059 | B12: Morning | F12: 5 | G12: 5.5 | H12: 6.5 | M12: =SUM(C12:L12) -> 17 | N12: =M12+M13 -> 29.5 | R12: =M12-P12-Q12 -> 17
B13: Evening | F13: 5 | G13: 5 | H13: 2.5 | M13: =SUM(C13:L13) -> 12.5 | R13: =M13-P13-Q13 -> 12.5
A14: 46060 | B14: Morning | F14: 5.5 | G14: 5 | H14: 4.5 | M14: =SUM(C14:L14) -> 15 | N14: =M14+M15 -> 27.5 | R14: =M14-P14-Q14 -> 15
B15: Evening | F15: 4.5 | G15: 5 | H15: 3 | M15: =SUM(C15:L15) -> 12.5 | R15: =M15-P15-Q15 -> 12.5
A16: 46061 | B16: Morning | F16: 5 | G16: 5.5 | H16: 4.7 | M16: =SUM(C16:L16) -> 15.2 | N16: =M16+M17 -> 29.2 | R16: =M16-P16-Q16 -> 15.2
B17: Evening | F17: 5.5 | G17: 5 | H17: 3.5 | M17: =SUM(C17:L17) -> 14 | R17: =M17-P17-Q17 -> 14
A18: 46062 | B18: Morning | F18: 4.5 | G18: 5 | H18: 4.5 | M18: =SUM(C18:L18) -> 14 | N18: =M18+M19 -> 27 | R18: =M18-P18-Q18 -> 14
B19: Evening | F19: 4 | G19: 5 | H19: 4 | M19: =SUM(C19:L19) -> 13 | R19: =M19-P19-Q19 -> 13
A20: 46063 | B20: Morning | F20: 5 | G20: 5.5 | H20: 4 | M20: =SUM(C20:L20) -> 14.5 | N20: =M20+M21 -> 29.2 | R20: =M20-P20-Q20 -> 14.5
B21: Evening | F21: 5.2 | G21: 5 | H21: 4.5 | M21: =SUM(C21:L21) -> 14.7 | R21: =M21-P21-Q21 -> 14.7
A22: 46064 | B22: Morning | F22: 4 | G22: 5 | H22: 2.5 | M22: =SUM(C22:L22) -> 11.5 | N22: =M22+M23 -> 23.7 | R22: =M22-P22-Q22 -> 11.5
B23: Evening | F23: 5 | G23: 5 | H23: 2.2 | M23: =SUM(C23:L23) -> 12.2 | R23: =M23-P23-Q23 -> 12.2
A24: 46065 | B24: Morning | F24: 4.5 | G24: 5 | H24: 4 | M24: =SUM(C24:L24) -> 13.5 | N24: =M24+M25 -> 26 | R24: =M24-P24-Q24 -> 13.5
B25: Evening | F25: 4 | G25: 5 | H25: 3.5 | M25: =SUM(C25:L25) -> 12.5 | R25: =M25-P25-Q25 -> 12.5
A26: 46066 | B26: Morning | F26: 4 | G26: 5 | H26: 3.2 | M26: =SUM(C26:L26) -> 12.2 | N26: =M26+M27 -> 24.7 | R26: =M26-P26-Q26 -> 12.2
B27: Evening | F27: 4.5 | G27: 4.5 | H27: 3.5 | M27: =SUM(C27:L27) -> 12.5 | R27: =M27-P27-Q27 -> 12.5
A28: 46067 | B28: Morning | F28: 4 | G28: 4.5 | H28: 3.5 | M28: =SUM(C28:L28) -> 12 | N28: =M28+M29 -> 24 | R28: =M28-P28-Q28 -> 12
B29: Evening | F29: 4 | G29: 5 | H29: 3 | M29: =SUM(C29:L29) -> 12 | R29: =M29-P29-Q29 -> 12
A30: 46068 | B30: Morning | F30: 4 | G30: 4 | H30: 3 | M30: =SUM(C30:L30) -> 11 | N30: =M30+M31 -> 22 | R30: =M30-P30-Q30 -> 11
B31: Evening | F31: 4 | G31: 4.5 | H31: 2.5 | M31: =SUM(C31:L31) -> 11 | R31: =M31-P31-Q31 -> 11
A32: 46069 | B32: Morning | F32: 4 | G32: 4 | H32: 2 | M32: =SUM(C32:L32) -> 10 | N32: =M32+M33 -> 21 | R32: =M32-P32-Q32 -> 10
B33: Evening | F33: 4 | G33: 4.5 | H33: 2.5 | M33: =SUM(C33:L33) -> 11 | R33: =M33-P33-Q33 -> 11
A34: 46070 | B34: Morning | F34: 4 | G34: 4.5 | H34: 3 | J34: 4.5 | K34: 4.1 | L34: 5 | M34: =SUM(C34:L34) -> 25.1 | N34: =M34+M35 -> 47.8 | R34: =M34-P34-Q34 -> 25.1
B35: Evening | F35: 4.2 | G35: 4.5 | H35: 1.5 | J35: 4 | K35: 4 | L35: 4.5 | M35: =SUM(C35:L35) -> 22.7 | R35: =M35-P35-Q35 -> 22.7
A36: 46071 | B36: Morning | F36: 4 | G36: 4.5 | H36: 3 | J36: 4 | K36: 4.3 | L36: 4.5 | M36: =SUM(C36:L36) -> 24.3 | N36: =M36+M37 -> 47.3 | R36: =M36-P36-Q36 -> 24.3
B37: Evening | F37: 4 | G37: 4 | H37: 2 | J37: 4 | K37: 4.5 | L37: 4.5 | M37: =SUM(C37:L37) -> 23 | R37: =M37-P37-Q37 -> 23
A38: 46072 | B38: Morning | F38: 4 | G38: 4.5 | H38: 4 | J38: 5 | K38: 4.5 | L38: 4.7 | M38: =SUM(C38:L38) -> 26.7 | N38: =M38+M39 -> 52.2 | R38: =M38-P38-Q38 -> 26.7
B39: Evening | F39: 4.5 | G39: 4.5 | H39: 3.5 | J39: 4.5 | K39: 4 | L39: 4.5 | M39: =SUM(C39:L39) -> 25.5 | R39: =M39-P39-Q39 -> 25.5
A40: 46073 | B40: Morning | F40: 5 | G40: 4.5 | H40: 2 | J40: 4.5 | K40: 4.5 | L40: 5 | M40: =SUM(C40:L40) -> 25.5 | N40: =M40+M41 -> 51.5 | R40: =M40-P40-Q40 -> 25.5
...

Sheet Mar 2026
A1: Datemm- | B1: Milking | C1: Shobha | D1: Devaki | E1: Sita | F1: Lakshmi | G1: Mruga | H1: Radha | I1: Shravani | J1: Uma | K1: Parvati | L1: Durga | M1: Total (Litres) | N1: Daily total (Litres) | P1: Transfer to milk sale | Q1: Transfer to ghee | R1: Balance milk | S1: satyajits home | T1: Amit bhave | U1: bal | V1: actual sale | W1: return from sale | X1: diff
A2: 46082 | B2: Morning | F2: 4.5 | G2: 4 | H2: 2 | I2: 3 | J2: 4.5 | K2: 4 | L2: 5.7 | M2: =SUM(C2:L2) -> 27.7 | N2: =M2+M3 -> 49.4 | P2: 17.5 | Q2: 10.2 | R2: =M2-P2-Q2 -> 0
B3: Evening | F3: 4 | G3: 2.5 | H3: 1 | I3: 3 | J3: 3.7 | K3: 2.5 | L3: 5 | M3: =SUM(C3:L3) -> 21.7 | P3: 0 | Q3: 21.7 | R3: =M3-P3-Q3 -> 0
A4: =A2+1 -> 46083 | B4: Morning | F4: 4.5 | G4: 4.5 | H4: 2 | I4: 3 | J4: 4.3 | K4: 4 | L4: 5.8 | M4: =SUM(C4:L4) -> 28.1 | N4: =M4+M5 -> 50 | P4: 25.25 | Q4: 2.85 | R4: =M4-P4-Q4 -> 0
B5: Evening | F5: 3.5 | G5: 2.5 | H5: 2 | I5: 2.5 | J5: 3 | K5: 4 | L5: 4.4 | M5: =SUM(C5:L5) -> 21.9 | P5: 0 | Q5: 21.9 | R5: =M5-P5-Q5 -> 0
A6: =A4+1 -> 46084 | B6: Morning | F6: 3.5 | G6: 2.5 | H6: 4 | I6: 2.5 | J6: 3.5 | K6: 2.5 | L6: 4.3 | M6: =SUM(C6:L6) -> 22.8 | N6: =M6+M7 -> 43.8 | P6: 20.75 | Q6: 2.05 | R6: =M6-P6-Q6 -> 0
B7: Evening | F7: 3.5 | G7: 1.5 | H7: 1.5 | I7: 2.5 | J7: 4 | K7: 2 | L7: 6 | M7: =SUM(C7:L7) -> 21 | P7: 0 | Q7: 21 | R7: =M7-P7-Q7 -> 0
A8: =A6+1 -> 46085 | B8: Morning | F8: 2 | G8: 2 | H8: 3.5 | I8: 3 | J8: 2.7 | K8: 3 | L8: 5.5 | M8: =SUM(C8:L8) -> 21.7 | N8: =M8+M9 -> 45.4 | P8: 21.7 | Q8: 0 | R8: =M8-P8-Q8 -> 0
B9: Evening | F9: 3.5 | G9: 2 | H9: 3 | I9: 2.7 | J9: 4 | K9: 3.7 | L9: 4.8 | M9: =SUM(C9:L9) -> 23.7 | P9: 0 | Q9: 23.7 | R9: =M9-P9-Q9 -> 0
A10: =A8+1 -> 46086 | B10: Morning | F10: 3.5 | G10: 2.5 | H10: 2.7 | I10: 3.5 | J10: 4.3 | K10: 4 | L10: 5.5 | M10: =SUM(C10:L10) -> 26 | N10: =M10+M11 -> 47.8 | P10: 24.75 | Q10: 1.25 | R10: =M10-P10-Q10 -> 0
B11: Evening | F11: 4 | G11: 2 | H11: 4 | I11: 1.8 | J11: 4.5 | L11: 5.5 | M11: =SUM(C11:L11) -> 21.8 | P11: 0 | Q11: 21.8 | R11: =M11-P11-Q11 -> 0
A12: =A10+1 -> 46087 | B12: Morning | F12: 3 | G12: 3 | H12: 3.5 | I12: 2.5 | J12: 4.3 | K12: 4 | L12: 5.2 | M12: =SUM(C12:L12) -> 25.5 | N12: =M12+M13 -> 45.7 | P12: 25.25 | Q12: 0.25 | R12: =M12-P12-Q12 -> 0
B13: Evening | F13: 3 | G13: 2.5 | H13: 2.5 | I13: 1 | J13: 3.7 | K13: 3.5 | L13: 4 | M13: =SUM(C13:L13) -> 20.2 | P13: 0 | Q13: 20.2 | R13: =M13-P13-Q13 -> 0
A14: =A12+1 -> 46088 | B14: Morning | F14: 4 | G14: 4 | H14: 4 | I14: 2 | J14: 4 | K14: 4 | L14: 5 | M14: =SUM(C14:L14) -> 27 | N14: =M14+M15 -> 45.5 | P14: 27 | Q14: 0 | R14: =M14-P14-Q14 -> 0
B15: Evening | F15: 3.5 | G15: 2.5 | H15: 1 | I15: 1 | J15: 3.5 | K15: 3 | L15: 4 | M15: =SUM(C15:L15) -> 18.5 | P15: 0 | Q15: 18.5 | R15: =M15-P15-Q15 -> 0
A16: =A14+1 -> 46089 | B16: Morning | F16: 4 | G16: 4 | I16: 1.5 | J16: 4 | K16: 4 | L16: 4 | M16: =SUM(C16:L16) -> 21.5 | N16: =M16+M17 -> 42 | P16: 26.75 | Q16: 0 | R16: =M16-P16-Q16 -> -5.25 | S16: 2 | T16: 3.25 | U16: =R16+S16+T16 -> 0 | V16: 25.75 | W16: =P16-V16 -> 1
B17: Evening | F17: 3 | G17: 2.5 | H17: 3 | I17: 1 | J17: 3.5 | K17: 3.5 | L17: 4 | M17: =SUM(C17:L17) -> 20.5 | P17: 0 | Q17: 20.5 | R17: =M17-P17-Q17 -> 0 | U17: =R17+S17+T17 -> 0 | W17: =P17-V17 -> 0
A18: =A16+1 -> 46090 | B18: Morning | F18: 3.5 | G18: 4 | H18: 2 | I18: 1 | J18: 4 | K18: 3 | L18: 4.5 | M18: =SUM(C18:L18) -> 22 | N18: =M18+M19 -> 43 | P18: 27.75 | Q18: 0 | R18: =M18-P18-Q18 -> -5.75 | S18: 2.25 | T18: 3.5 | U18: =R18+S18+T18 -> 0 | V18: 25.25 | W18: =P18-V18 -> 2.5
B19: Evening | F19: 3 | G19: 2.5 | H19: 2 | I19: 2.5 | J19: 3 | K19: 3.7 | L19: 4.5 | M19: 21 | P19: 11 | Q19: 10 | R19: =M19-P19-Q19 -> 0 | U19: =R19+S19+T19 -> 0 | W19: =P19-V19 -> 11
A20: =A18+1 -> 46091 | B20: Morning | F20: 3 | G20: 3 | H20: 4 | I20: 1 | J20: 4.5 | K20: 4 | L20: 4.5 | M20: =SUM(C20:L20) -> 24 | N20: =M20+M21 -> 43 | P20: 25.5 | Q20: 0 | R20: =M20-P20-Q20 -> -1.5 | S20: 0 | T20: 0 | U20: =R20+S20+T20 -> -1.5 | V20: 25.5 | W20: =P20-V20 -> 0
B21: Evening | F21: 3 | G21: 2.5 | H21: 1.5 | I21: 2 | J21: 3 | K21: 3 | L21: 4 | M21: =SUM(C21:L21) -> 19 | P21: 0 | Q21: 19 | R21: =M21-P21-Q21 -> 0 | U21: =R21+S21+T21 -> 0 | W21: =P21-V21 -> 0
A22: =A20+1 -> 46092 | B22: Morning | F22: 3.5 | G22: 3.5 | H22: 3 | I22: 2 | J22: 4 | K22: 4 | L22: 5 | M22: =SUM(C22:L22) -> 25 | N22: =M22+M23 -> 46 | P22: 29.25 | Q22: 0 | R22: =M22-P22-Q22 -> -4.25 | S22: 1.25 | T22: 3 | U22: =R22+S22+T22 -> 0 | V22: 28.75 | W22: =P22-V22 -> 0.5
B23: Evening | F23: 3.5 | G23: 2.5 | H23: 3 | I23: 1.5 | J23: 3 | K23: 3 | L23: 4.5 | M23: =SUM(C23:L23) -> 21 | P23: 0 | Q23: 21 | R23: =M23-P23-Q23 -> 0 | U23: =R23+S23+T23 -> 0 | W23: =P23-V23 -> 0
A24: =A22+1 -> 46093 | B24: Morning | F24: 4 | G24: 4 | H24: 3 | I24: 2 | J24: 4 | K24: 4 | L24: 5 | M24: =SUM(C24:L24) -> 26 | N24: =M24+M25 -> 46.5 | P24: 28.9 | Q24: 0 | R24: =M24-P24-Q24 -> -2.9 | S24: 0 | T24: 2.9 | U24: =R24+S24+T24 -> 0 | V24: 26.25 | W24: =P24-V24 -> 2.65
B25: Evening | F25: 3.5 | G25: 2.5 | H25: 3.5 | I25: 1 | J25: 3 | K25: 3 | L25: 4 | M25: =SUM(C25:L25) -> 20.5 | P25: 0 | Q25: 20.5 | R25: =M25-P25-Q25 -> 0 | T25: 0 | U25: =R25+S25+T25 -> 0 | W25: =P25-V25 -> 0
A26: =A24+1 -> 46094 | B26: Morning | F26: 4.25 | G26: 4 | H26: 3.5 | I26: 2.5 | J26: 4 | K26: 4 | L26: 5 | M26: =SUM(C26:L26) -> 27.25 | N26: =M26+M27 -> 46.25 | O26: 0 | P26: 31.45 | Q26: 0 | R26: =M26-P26-Q26 -> -4.2 | T26: 4.2 | U26: =R26+S26+T26 -> 0 | V26: 30.25 | W26: =P26-V26 -> 1.2
B27: Evening | F27: 3 | G27: 2.5 | H27: 2.5 | I27: 1 | J27: 3 | K27: 3 | L27: 4 | M27: =SUM(C27:L27) -> 19 | P27: 0 | Q27: 19 | R27: =M27-P27-Q27 -> 0 | U27: =R27+S27+T27 -> 0 | W27: =P27-V27 -> 0
A28: =A26+1 -> 46095 | B28: Morning | F28: 4.5 | G28: 4 | H28: 3 | I28: 2 | J28: 4 | K28: 4 | L28: 5 | M28: =SUM(C28:L28) -> 26.5 | N28: =M28+M29 -> 45.5 | P28: 29.75 | Q28: 0 | R28: =M28-P28-Q28 -> -3.25 | T28: 3.25 | U28: =R28+S28+T28 -> 0 | V28: 27.25 | W28: =P28-V28 -> 2.5
B29: Evening | F29: 3 | G29: 2.5 | H29: 2.5 | I29: 1 | J29: 3 | K29: 3 | L29: 4 | M29: =SUM(C29:L29) -> 19 | Q29: 19 | R29: =M29-P29-Q29 -> 0 | U29: =R29+S29+T29 -> 0 | W29: =P29-V29 -> 0
A30: =A28+1 -> 46096 | B30: Morning | F30: 4 | G30: 4 | H30: 3 | I30: 2 | J30: 4 | K30: 4 | L30: 4.75 | M30: =SUM(C30:L30) -> 25.75 | N30: =M30+M31 -> 45.75 | P30: 28.75 | Q30: 0 | R30: =M30-P30-Q30 -> -3 | T30: 3 | U30: =R30+S30+T30 -> 0 | V30: 25.25 | W30: =P30-V30 -> 3.5
B31: Evening | F31: 3.5 | G31: 2.5 | H31: 2.5 | I31: 1.5 | J31: 3 | K31: 3 | L31: 4 | M31: =SUM(C31:L31) -> 20 | Q31: 20 | R31: =M31-P31-Q31 -> 0 | U31: =R31+S31+T31 -> 0 | W31: =P31-V31 -> 0
A32: =A30+1 -> 46097 | B32: Morning | F32: 4 | G32: 4 | H32: 2 | I32: 2 | J32: 4 | K32: 4 | L32: 4.5 | M32: =SUM(C32:L32) -> 24.5 | N32: =M32+M33 -> 44.5 | P32: 29.7 | Q32: 0 | R32: =M32-P32-Q32 -> -5.2 | S32: 2 | T32: 3.2 | U32: =R32+S32+T32 -> 0 | V32: 27.73 | W32: =P32-V32 -> 1.97 | X32: =P32-V32-W32 -> 0
B33: Evening | F33: 3 | G33: 2.5 | H33: 3 | I33: 1.5 | J33: 3 | K33: 3 | L33: 4 | M33: 20 | Q33: 20 | R33: =M33-P33-Q33 -> 0 | U33: =R33+S33+T33 -> 0 | X33: =P33-V33-W33 -> 0
A34: =A32+1 -> 46098 | B34: Morning | F34: 4 | G34: 4 | H34: 3 | I34: 2 | J34: 4 | K34: 4 | L34: 433 3- | M34: =SUM(C34:L34) -> 21 | N34: =M34+M35 -> 41 | P34: 29.3 | Q34: 0 | R34: =M34-P34-Q34 -> -8.3 | S34: 1 | T34: 2.8 | U34: =R34+S34+T34 -> -4.5 | V34: 29.5 | W34: 0 | X34: =P34-V34-W34 -> -0.2
B35: Evening | F35: 3.5 | G35: 2.5 | H35: 2.5 | I35: 2 | J35: 3 | K35: 3 | L35: 3.5 | M35: =SUM(C35:L35) -> 20 | R35: =M35-P35-Q35 -> 20 | U35: =R35+S35+T35 -> 20 | X35: =P35-V35-W35 -> 0
A36: =A34+1 -> 46099 | B36: Morning | F36: 4 | G36: 4 | H36: 3 | I36: 2 | J36: 4 | K36: 4 | L36: 4 | M36: =SUM(C36:L36) -> 25 | N36: =M36+M37 -> 45 | P36: 29 | Q36: 0 | R36: =M36-P36-Q36 -> -4 | S36: 1 | T36: 3 | U36: =R36+S36+T36 -> 0 | V36: 27 | W36: 2 | X36: =P36-V36-W36 -> 0
B37: Evening | F37: 3.5 | G37: 2.5 | H37: 2.5 | I37: 2 | J37: 3 | K37: 3 | L37: 3.5 | M37: =SUM(C37:L37) -> 20 | R37: =M37-P37-Q37 -> 20 | U37: =R37+S37+T37 -> 20 | X37: =P37-V37-W37 -> 0
A38: =A36+1 -> 46100 | B38: Morning | F38: 4 | G38: 4 | H38: 3 | I38: 2.5 | J38: 4 | K38: 4 | L38: 4.5 | M38: =SUM(C38:L38) -> 26 | N38: =M38+M39 -> 46 | P38: 29.9 | Q38: 0 | R38: =M38-P38-Q38 -> -3.9 | S38: 1 | T38: 2.9 | U38: =R38+S38+T38 -> 0 | V38: 29.9 | W38: 0.5 | X38: =P38-V38-W38 -> -0.5
B39: Evening | F39: 3.5 | G39: 2.5 | H39: 2.5 | I39: 2 | J39: 3 | K39: 3 | L39: 3.5 | M39: =SUM(C39:L39) -> 20 | R39: =M39-P39-Q39 -> 20 | U39: =R39+S39+T39 -> 20 | X39: =P39-V39-W39 -> 0
A40: =A38+1 -> 46101 | B40: Morning | F40: 4 | G40: 4 | H40: 2.5 | I40: 3 | J40: 4 | K40: 4 | L40: 4.5 | M40: =SUM(C40:L40) -> 26 | N40: =M40+M41 -> 46 | P40: 31.1 | Q40: 0 | R40: =M40-P40-Q40 -> -5.1 | S40: 1.5 | T40: 3.6 | U40: =R40+S40+T40 -> 0 | V40: 29.72 | W40: 2 | X40: =P40-V40-W40 -> -0.62
...

Sheet Sheet15

Sheet April 2026
A1: Datemm- | B1: Milking | C1: Shobha | D1: Devaki | E1: Sita | F1: Lakshmi | G1: Mruga | H1: Radha | I1: Shravani | J1: Uma | K1: Parvati | L1: Durga | M1: Ganga | N1: Yamuna | P1: Total (Litres) | Q1: Daily total (Litres) | S1: Transfer to milk sale | T1: Transfer to ghee | U1: Balance milk | V1: stored milk | W1: satyajits home | X1: Amit bhave | Y1: bal | Z1: actual sale | AA1: return from sale | AB1: diff | AC1: bal
A2: 46113 | B2: Morning | F2: 4 | G2: 4 | H2: 3 | I2: 3 | J2: 4 | K2: 4.5 | L2: 5 | P2: =SUM(C2:N2) -> 27.5 | Q2: =P2+P3 -> 45 | S2: 34 | T2: 0 | U2: =P2-S2-T2 -> -6.5 | W2: 1.5 | X2: 5 | Y2: =U2+W2+X2 -> 0 | Z2: 36 | AA2: 0
B3: Evening | F3: 3 | G3: 2.5 | H3: 1 | I3: 1.5 | J3: 3 | K3: 2.5 | L3: 4 | P3: =SUM(C3:N3) -> 17.5 | S3: 2.5 | T3: 15 | U3: =P3-S3-T3 -> 0 | W3: 0
A4: 46114 | B4: Morning | F4: 4 | G4: 4 | H4: 2.5 | I4: 2.5 | J4: 4 | K4: 4 | L4: 5 | P4: =SUM(C4:N4) -> 26 | Q4: =P4+P5 -> 44.5 | S4: 32.5 | T4: 0 | U4: =P4-S4-T4 -> -6.5 | W4: 1.5 | X4: 5 | Y4: 0 | Z4: 33 | AA4: 0
B5: Evening | F5: 3.5 | G5: 2 | H5: 1.5 | I5: 2 | J5: 3 | K5: 2.5 | L5: 4 | P5: =SUM(C5:N5) -> 18.5 | S5: 1 | T5: 17.5 | U5: =P5-S5-T5 -> 0 | W5: 0 | AC5: 32.6 | AD5: 7.5
A6: 46115 | B6: Morning | F6: 4 | G6: 4 | H6: 2.5 | I6: 2.5 | J6: 4 | K6: 4 | L6: 5 | P6: =SUM(C6:N6) -> 26 | Q6: =P6+P7 -> 45.5 | S6: 35.7 | T6: 0 | U6: =P6-S6-T6 -> -9.7 | W6: 4.5 | X6: 5.2 | Y6: 0 | Z6: 37 | AA6: 1.6
B7: Evening | F7: 3.5 | G7: 2 | H7: 2.5 | I7: 2 | J7: 3 | K7: 2.5 | L7: 4 | P7: =SUM(C7:N7) -> 19.5 | S7: 2.5 | T7: 17 | U7: =P7-S7-T7 -> 0
A8: 46116 | B8: Morning | F8: 4 | G8: 4 | H8: 2 | I8: 2 | J8: 4 | K8: 4 | L8: 4.5 | P8: =SUM(C8:N8) -> 24.5 | Q8: =P8+P9 -> 44 | S8: 32.97 | T8: 11 | Z8: 32.97 | AA8: 0
B9: Evening | F9: 3.5 | G9: 2.5 | H9: 2 | I9: 2 | J9: 3 | K9: 2.5 | L9: 4 | P9: =SUM(C9:N9) -> 19.5
A10: 46117 | B10: Morning | F10: 4 | G10: 4 | H10: 2.5 | I10: 2.5 | J10: 4 | K10: 4 | L10: 4.5 | P10: =SUM(C10:N10) -> 25.5 | Q10: =P10+P11 -> 44.5 | S10: 35.47 | T10: 8.5 | W10: 0 | X10: 0 | Z10: 35.47 | AA10: 0
B11: Evening | F11: 3.5 | G11: 2.5 | H11: 2 | I11: 2 | J11: 2.5 | K11: 2.5 | L11: 4 | P11: =SUM(C11:N11) -> 19
A12: 46118 | B12: Morning | F12: 4 | G12: 4 | H12: 1 | I12: 2 | J12: 4 | K12: 4 | L12: 4.5 | P12: =SUM(C12:N12) -> 23.5 | Q12: =P12+P13 -> 44 | S12: 34.97 | W12: 0 | X12: 0 | Z12: 34.97 | AA12: 0.25
B13: Evening | F13: 4 | G13: 3 | H13: 2 | I13: 2 | J13: 3 | K13: 2.5 | L13: 4 | P13: =SUM(C13:N13) -> 20.5
A14: 46119 | B14: Morning | F14: 4 | G14: 4 | H14: 1 | I14: 2 | J14: 4 | K14: 4 | L14: 4.5 | P14: =SUM(C14:N14) -> 23.5 | Q14: =P14+P15 -> 42.5 | S14: =Q14-T14 -> 37.5 | T14: 5 | Z14: 35.97
B15: Evening | F15: 3.5 | G15: 2.5 | H15: 2 | I15: 2 | J15: 3 | K15: 2 | L15: 4 | P15: =SUM(C15:N15) -> 19
A16: 46120 | B16: Morning | F16: 4 | G16: 4 | H16: 2 | I16: 2.5 | J16: 4 | K16: 4 | L16: 4 | P16: =SUM(C16:N16) -> 24.5 | Q16: =P16+P17 -> 44.5 | Z16: 35.47
B17: Evening | F17: 4 | G17: 3 | H17: 2 | I17: 2 | J17: 3 | K17: 2 | L17: 4 | P17: =SUM(C17:N17) -> 20
A18: 46121 | B18: Morning | F18: 4.5 | G18: 4 | H18: 2 | I18: 2 | J18: 3.5 | K18: 4 | L18: 4.5 | P18: =SUM(C18:N18) -> 24.5 | Q18: =P18+P19 -> 43.9 | Z18: 36.47
B19: Evening | F19: 3.5 | G19: 2.5 | H19: 2 | I19: 1.5 | J19: 3 | K19: 2.9 | L19: 4 | P19: =SUM(C19:N19) -> 19.4
A20: 46122 | B20: Morning | F20: 4 | G20: 4 | H20: 1 | I20: 2 | J20: 4 | K20: 4 | L20: 4.4 | P20: =SUM(C20:N20) -> 23.4 | Q20: =P20+P21 -> 45.3 | Z20: 38.47 | AA20: 2
B21: Evening | F21: 4 | G21: 3 | H21: 2.5 | I21: 2.5 | J21: 3 | K21: 2.9 | L21: 4 | P21: =SUM(C21:N21) -> 21.9
A22: 46123 | B22: Morning | F22: 4 | G22: 4 | H22: 2.5 | I22: 2.2 | J22: 4 | K22: 4 | L22: 4.5 | M22: 2.5 | N22: 2 | P22: =SUM(C22:N22) -> 29.7 | Q22: =P22+P23 -> 54.2 | Z22: 40.22 | AA22: 1
B23: Evening | F23: 3.5 | G23: 2.5 | H23: 1 | I23: 2 | J23: 3 | K23: 3 | L23: 4 | M23: 2.5 | N23: 3 | P23: =SUM(C23:N23) -> 24.5
